Workbook

Sheet Form Responses 1
A1: Timestamp | B1: เพศสภาพร่างกาย | C1: อายุ | D1: ส่วนสูง (cm.) ตัวอย่าง 170 | E1: น้ำหนัก (Kg.) ตัวอย่าง 70 | F1: ค่าองศาเริ่มต้นที่วัด Pitch และ Roll ของท่าน ตัวอย่าง p(pitch) = x.xx , r(Roll) = x.xx | G1: โดยปกติคุณนั่งทำงาน/เรียนหน้าคอมพิวเตอร์เฉลี่ยวันละกี่ชั่วโมง? | H1: คุณมีอาการปวดหลัง คอ บ่า ไหล่ (Office Syndrome) เป็นประจำหรือไม่? | I1: ท่านยินยอมให้เก็บรวบรวมและใช้ข้อมูลส่วนบุคคลของท่านหรือไม่? | J1: ด้านที่ 1 : อุปกรณ์ฮาร์ดแวร์ (Hardware & Sensor) [ขนาดและน้ำหนักของอุปกรณ์มีความกะทัดรัด ไม่เกะกะ] | K1: ด้านที่ 1 : อุปกรณ์ฮาร์ดแวร์ (Hardware & Sensor) [อุปกรณ์สามารถสวมใส่ หรือติดตั้งใช้งานได้ง่าย ไม่ซับซ้อน] | L1: ด้านที่ 1 : อุปกรณ์ฮาร์ดแวร์ (Hardware & Sensor) [ความรู้สึกสบายเมื่อต้องใช้งานอุปกรณ์ติดต่อกันเป็นเวลานาน] | M1: ด้านที่ 1 : อุปกรณ์ฮาร์ดแวร์ (Hardware & Sensor) [อุปกรณ์ไม่ก่อให้เกิดความร้อนจนรบกวนการใช้งาน] | N1: ด้านที่ 1 : อุปกรณ์ฮาร์ดแวร์ (Hardware & Sensor) [ความทนทานและรูปแบบการจัดเก็บสายไฟ/ตัวบอร์ด ดูปลอดภัยและเรียบร้อย] | O1: ด้านที่ 2: แอปพลิเคชันและการแสดงผล (Software & User Interface) [การออกแบบหน้าจอแอปพลิเคชัน (UI) มีความสวยงาม ทันสมัย] | P1: ด้านที่ 2: แอปพลิเคชันและการแสดงผล (Software & User Interface) [ความรวดเร็วของการคำนวณและแสดงผลคะแนนรวมของการนั่ง] | Q1: ด้านที่ 2: แอปพลิเคชันและการแสดงผล (Software & User Interface) [หน้าแสดงประวัติ (History) และการสรุปข้อมูล เข้าใจง่าย ช่วยให้ท่านเห็นแนวโน้มพฤติกรรมของตนเองได้ชัดเจน] | R1: ด้านที่ 2: แอปพลิเคชันและการแสดงผล (Software & User Interface) [ข้อความคำแนะนำ (Advice) มีความเหมาะสม เข้าใจง่าย และน่าสนใจ] | S1: ด้านที่ 2: แอปพลิเคชันและการแสดงผล (Software & User Interface) [ระดับภาษาที่ระบบใช้แจ้งเตือน (ชมเชย, แนะนำ, ตักเตือน) ช่วยสร้างแรงจูงใจได้ดี] | T1: ด้านที่ 3: ประโยชน์ต่อสุขภาพและการนำไปใช้งานจริง (Health Impact & Practicality) [ระบบนี้ช่วยให้คุณตระหนักรู้ (Awareness) ถึงท่านั่งที่ผิดปกติของตนเองได้เร็วขึ้น] | U1: ด้านที่ 3: ประโยชน์ต่อสุขภาพและการนำไปใช้งานจริง (Health Impact & Practicality) [ข้อความแจ้งเตือนช่วยกระตุ้นให้คุณอยากปรับเปลี่ยนท่านั่งให้ถูกต้อง] | V1: ด้านที่ 3: ประโยชน์ต่อสุขภาพและการนำไปใช้งานจริง (Health Impact & Practicality) [หากใช้งานเป็นประจำ คุณเชื่อว่าระบบนี้จะช่วยลดอาการปวดหลัง/ออฟฟิศซินโดรมได้] | W1: ด้านที่ 3: ประโยชน์ต่อสุขภาพและการนำไปใช้งานจริง (Health Impact & Practicality) [ความเหมาะสมของระบบนี้ในการนำไปใช้จริงในชีวิตประจำวัน (เวลาทำงาน/เรียน)] | X1: ด้านที่ 3: ประโยชน์ต่อสุขภาพและการนำไปใช้งานจริง (Health Impact & Practicality) [ความพึงพอใจในภาพรวม] | Y1: ข้อเสนอแนะ และปรับปรุง
A2: 46094.605 | B2: หญิง | C2: 18-29 ปี | D2: 150 | E2: 80 | F2: p=55.60, r=-3.14 | G2: มากกว่า 8 ชั่วโมง | H2: มี | I2: ยินยอม | J2: ดีเยี่ยม | K2: ปานกลาง | L2: ดี | M2: ดีเยี่ยม | N2: ดีเยี่ยม | O2: ดี | P2: ดี | Q2: ดี | R2: ดี | S2: ดีเยี่ยม | T2: ดี | U2: ดีเยี่ยม | V2: ดี | W2: ดี | X2: ดี | Y2: อุปกรณ์ใส่ยาก ตัวแอปตอนเริ่มต้นไม่รู้ว่าต้องกดตรงไหนก่อน
A3: 46094.635 | B3: ชาย | C3: 18-29 ปี | D3: 167 | E3: 70 | F3: P=69.00.r=-0.79 | G3: 4 - 8 ชั่วโมง | H3: เป็นบางครั้งบางคราว | I3: ยินยอม | J3: ดีเยี่ยม | K3: ดี | L3: ดีเยี่ยม | M3: ดีเยี่ยม | N3: ดีเยี่ยม | O3: ดี | P3: ดีเยี่ยม | Q3: ดีเยี่ยม | R3: ดีเยี่ยม | S3: ดีเยี่ยม | T3: ดี | U3: ดี | V3: ดีเยี่ยม | W3: ดีเยี่ยม | X3: ดี | Y3: ใส่ยาก
A4: 46094.677 | B4: หญิง | C4: 18-29 ปี | D4: 160 | E4: 100 | F4: P=65.10, R=1.08 | G4: มากกว่า 8 ชั่วโมง | H4: มี | I4: ยินยอม | J4: ดี | K4: ดี | L4: ปานกลาง | M4: ดีเยี่ยม | N4: ดีเยี่ยม | O4: ดีเยี่ยม | P4: ดี | Q4: ดี | R4: ดีเยี่ยม | S4: ดีเยี่ยม | T4: ดี | U4: ดีเยี่ยม | V4: ดีเยี่ยม | W4: ดี | X4: ดีเยี่ยม | Y4: อาจจะไม่เหมาะกับคนอ้วนเพราะมันทำให้เจ็บช่วงท้อง อาจจะใส่ยากสำหรับช่วงแรก
A5: 46094.824 | B5: หญิง | C5: 45-59 ปี | D5: 150 | E5: 48 | F5: P=62.28,R=0.22 | G5: 4 - 8 ชั่วโมง | H5: เป็นบางครั้งบางคราว | I5: ยินยอม | J5: ดี | K5: ดี | L5: ปานกลาง | M5: ปานกลาง | N5: ปานกลาง | O5: ดี | P5: ดี | Q5: ดี | R5: ดี | S5: ดี | T5: ดีเยี่ยม | U5: ดีเยี่ยม | V5: ดีเยี่ยม | W5: ดีเยี่ยม | X5: ดีเยี่ยม | Y5: อุปกรณ์ควรใช้ระบบเชื่อมต่อแบบไร้สาย การใส่ควรให้สะดวกกว่านี้
A6: 46095.807 | B6: ชาย | C6: 45-59 ปี | D6: 160 | E6: 80 | F6: P=61.12,R=0.69 | G6: 4 - 8 ชั่วโมง | H6: เป็นบางครั้งบางคราว | I6: ยินยอม | J6: ดีเยี่ยม | K6: ดีเยี่ยม | L6: ดี | M6: ดีเยี่ยม | N6: ดีเยี่ยม | O6: ดีเยี่ยม | P6: ดีเยี่ยม | Q6: ดีเยี่ยม | R6: ดีเยี่ยม | S6: ดีเยี่ยม | T6: ดีเยี่ยม | U6: ดีเยี่ยม | V6: ดีเยี่ยม | W6: ดีเยี่ยม | X6: ดีเยี่ยม
A7: 46095.84 | B7: หญิง | C7: 45-59 ปี | D7: 160 | E7: 110 | F7: P=57.23,R=-1.90 | G7: น้อยกว่า 4 ชั่วโมง | H7: ไม่มี | I7: ยินยอม | J7: ดีเยี่ยม | K7: ดี | L7: ดี | M7: ดีเยี่ยม | N7: ดี | O7: ดี | P7: ดีเยี่ยม | Q7: ดีเยี่ยม | R7: ดี | S7: ดีเยี่ยม | T7: ดี | U7: ดีเยี่ยม | V7: ดีเยี่ยม | W7: ดีเยี่ยม | X7: ดีเยี่ยม | Y7: ไม่มีข้อเสนอแนะ
A8: 46095.848 | B8: ชาย | C8: 60 ปีขึ้นไป | D8: 165 | E8: 48 | F8: p=75.62, r=0.86 | G8: น้อยกว่า 4 ชั่วโมง | H8: ไม่มี | I8: ยินยอม | J8: ดีเยี่ยม | K8: ปานกลาง | L8: ดี | M8: ดีเยี่ยม | N8: ดีเยี่ยม | O8: ดีเยี่ยม | P8: ดีเยี่ยม | Q8: ดีเยี่ยม | R8: ดี | S8: ดี | T8: ดีเยี่ยม | U8: ดี | V8: ดีเยี่ยม | W8: ดีเยี่ยม | X8: ดีเยี่ยม
A9: 46095.855 | B9: หญิง | C9: 18-29 ปี | D9: 150 | E9: 60 | F9: p=51.72, r=-0.50 | G9: มากกว่า 8 ชั่วโมง | H9: มี | I9: ยินยอม | J9: ดีเยี่ยม | K9: ดี | L9: ดีเยี่ยม | M9: ดีเยี่ยม | N9: ดีเยี่ยม | O9: ดีเยี่ยม | P9: ดีเยี่ยม | Q9: ดีเยี่ยม | R9: ดี | S9: ดี | T9: ดีเยี่ยม | U9: ดีเยี่ยม | V9: ดีเยี่ยม | W9: ดี | X9: ดีเยี่ยม
A10: 46100.906 | B10: หญิง | C10: 18-29 ปี | D10: 165 | E10: 54 | F10: p(pitch)=54.98, r(Roll)=-4.29 | G10: 4 - 8 ชั่วโมง | H10: เป็นบางครั้งบางคราว | I10: ยินยอม | J10: ดี | K10: ดี | L10: ดี | M10: ดีเยี่ยม | N10: ดีเยี่ยม | O10: ดีเยี่ยม | P10: ดีเยี่ยม | Q10: ดีเยี่ยม | R10: ดีเยี่ยม | S10: ดีเยี่ยม | T10: ดี | U10: ดีเยี่ยม | V10: ดีเยี่ยม | W10: ดี | X10: ดี | Y10: สายไฟค่อนข้างเกะกะ
A11: 3/26/2026 0:14:53 | B11: หญิง | C11: 18-29 ปี | D11: 172 | E11: 56 | F11: p = 56.22 , r = 7.62 | G11: 4 - 8 ชั่วโมง | H11: มี | I11: ยินยอม | J11: ดีเยี่ยม | K11: ดี | L11: ดีเยี่ยม | M11: ดีเยี่ยม | N11: ดีเยี่ยม | O11: ดีเยี่ยม | P11: ดีเยี่ยม | Q11: ดีเยี่ยม | R11: ดีเยี่ยม | S11: ดีเยี่ยม | T11: ดีเยี่ยม | U11: ดี | V11: ดีเยี่ยม | W11: ดีเยี่ยม | X11: ดีเยี่ยม
A12: 3/26/2026 0:16:51 | B12: หญิง | C12: 18-29 ปี | D12: 172 | E12: 56 | F12: p =39.73 ,r = 6.73 | G12: 4 - 8 ชั่วโมง | H12: เป็นบางครั้งบางคราว | I12: ยินยอม | J12: ดีเยี่ยม | K12: ดีเยี่ยม | L12: ดีเยี่ยม | M12: ดีเยี่ยม | N12: ดีเยี่ยม | O12: ดีเยี่ยม | P12: ดีเยี่ยม | Q12: ดีเยี่ยม | R12: ดีเยี่ยม | S12: ดีเยี่ยม | T12: ดีเยี่ยม | U12: ดีเยี่ยม | V12: ดีเยี่ยม | W12: ดีเยี่ยม | X12: ดีเยี่ยม
A13: 3/26/2026 0:50:10 | B13: หญิง | C13: 18-29 ปี | D13: 165 | E13: 99 | F13: p33.8 r17.67 | G13: 4 - 8 ชั่วโมง | H13: มี | I13: ยินยอม | J13: ดีเยี่ยม | K13: ดีเยี่ยม | L13: ปานกลาง | M13: ดีเยี่ยม | N13: ดี | O13: ดี | P13: ดีเยี่ยม | Q13: ดีเยี่ยม | R13: ดี | S13: ดีเยี่ยม | T13: ดีเยี่ยม | U13: ดีเยี่ยม | V13: ดีเยี่ยม | W13: ดีเยี่ยม | X13: ดีเยี่ยม
A14: 3/27/2026 1:57:17 | B14: หญิง | C14: 30-44 ปี | D14: 152 | E14: 50 | F14: p=56.31 ,r=-0.98 | G14: มากกว่า 8 ชั่วโมง | H14: มี | I14: ยินยอม | J14: ดี | K14: ดี | L14: ดี | M14: ดีเยี่ยม | N14: ดี | O14: ดี | P14: ดี | Q14: ดี | R14: ดี | S14: ดีเยี่ยม | T14: ดี | U14: ดีเยี่ยม | V14: ดี | W14: ปานกลาง | X14: ดี | Y14: อุปกรณ์ใส่ยาก
A15: 3/27/2026 1:57:58 | B15: หญิง | C15: 18-29 ปี | D15: 151 | E15: 58 | F15: p=52.09, r=-1.28 | G15: มากกว่า 8 ชั่วโมง | H15: มี | I15: ยินยอม | J15: ดีเยี่ยม | K15: ปานกลาง | L15: ดี | M15: ดีเยี่ยม | N15: ดี | O15: ดี | P15: ดีเยี่ยม | Q15: ดีเยี่ยม | R15: ดี | S15: ดี | T15: ดีเยี่ยม | U15: ดี | V15: ดี | W15: ดี | X15: ดีเยี่ยม | Y15: ใส่ยาก
A16: 3/27/2026 2:21:21 | B16: ชาย | C16: 18-29 ปี | D16: 165 | E16: 75 | F16: P=56.73 R0.34 | G16: 4 - 8 ชั่วโมง | H16: เป็นบางครั้งบางคราว | I16: ยินยอม | J16: ดี | K16: ดี | L16: ดีเยี่ยม | M16: ดีเยี่ยม | N16: ดีเยี่ยม | O16: ดี | P16: ดีเยี่ยม | Q16: ดีเยี่ยม | R16: ดีเยี่ยม | S16: ดีเยี่ยม | T16: ดี | U16: ดี | V16: ดีเยี่ยม | W16: ดีเยี่ยม | X16: ดีเยี่ยม | Y16: ใส่ยากนิดนึง
A17: 3/27/2026 11:26:16 | B17: หญิง | C17: 18-29 ปี | D17: 160 | E17: 100 | F17: P=62.65 R=1.46 | G17: 4 - 8 ชั่วโมง | H17: มี | I17: ยินยอม | J17: ดี | K17: ดีเยี่ยม | L17: ดีเยี่ยม | M17: ดีเยี่ยม | N17: ดีเยี่ยม | O17: ดีเยี่ยม | P17: ดีเยี่ยม | Q17: ดีเยี่ยม | R17: ดีเยี่ยม | S17: ดีเยี่ยม | T17: ดีเยี่ยม | U17: ดีเยี่ยม | V17: ดีเยี่ยม | W17: ดี | X17: ดีเยี่ยม | Y17: -
A18: 3/27/2026 14:17:58 | B18: หญิง | C18: 18-29 ปี | D18: 161 | E18: 68 | F18: P(pitch)=27.32788, r(roll)=8.112443 | G18: มากกว่า 8 ชั่วโมง | H18: มี | I18: ยินยอม | J18: ดีเยี่ยม | K18: ดี | L18: ดี | M18: ดีเยี่ยม | N18: ดี | O18: ดี | P18: ดีเยี่ยม | Q18: ดีเยี่ยม | R18: ดีเยี่ยม | S18: ดีเยี่ยม | T18: ดีเยี่ยม | U18: ดีเยี่ยม | V18: ดี | W18: ดี | X18: ดี
A19: 3/27/2026 14:21:04 | B19: หญิง | C19: 18-29 ปี | D19: 161 | E19: 68 | F19: P(pitch)=51.2497, r(roll)=2.95061 | G19: มากกว่า 8 ชั่วโมง | H19: มี | I19: ยินยอม | J19: ดีเยี่ยม | K19: ดี | L19: ดี | M19: ดีเยี่ยม | N19: ดี | O19: ดี | P19: ดีเยี่ยม | Q19: ดีเยี่ยม | R19: ดีเยี่ยม | S19: ดี | T19: ดีเยี่ยม | U19: ดีเยี่ยม | V19: ดี | W19: ดี | X19: ดีเยี่ยม
A20: 3/27/2026 19:33:22 | B20: หญิง | C20: 30-44 ปี | D20: 156 | E20: 50 | F20: P=67.94 R=-1.23 | G20: 4 - 8 ชั่วโมง | H20: เป็นบางครั้งบางคราว | I20: ยินยอม | J20: ดี | K20: ดี | L20: ดี | M20: ดี | N20: ดี | O20: ดี | P20: ดี | Q20: ดี | R20: ดี | S20: ดี | T20: ดี | U20: ดี | V20: ดี | W20: ดี | X20: ดี
A21: 3/27/2026 20:02:41 | B21: ชาย | C21: 30-44 ปี | D21: 160 | E21: 80 | F21: P= 77.85 , R=0.92 | G21: 4 - 8 ชั่วโมง | H21: เป็นบางครั้งบางคราว | I21: ยินยอม | J21: ดีเยี่ยม | K21: ดีเยี่ยม | L21: ดีเยี่ยม | M21: ดีเยี่ยม | N21: ดีเยี่ยม | O21: ดีเยี่ยม | P21: ดีเยี่ยม | Q21: ดีเยี่ยม | R21: ดีเยี่ยม | S21: ดีเยี่ยม | T21: ดีเยี่ยม | U21: ดีเยี่ยม | V21: ดีเยี่ยม | W21: ดีเยี่ยม | X21: ดีเยี่ยม
A22: 3/30/2026 18:42:24 | B22: หญิง | C22: 18-29 ปี | D22: 169 | E22: 55.5 | F22: 6.2 , 1.69 | G22: มากกว่า 8 ชั่วโมง | H22: มี | I22: ยินยอม | J22: ดีเยี่ยม | K22: ดีเยี่ยม | L22: ดี | M22: ดีเยี่ยม | N22: ดี | O22: ดีเยี่ยม | P22: ปานกลาง | Q22: ปานกลาง | R22: ดี | S22: ดีเยี่ยม | T22: ดีเยี่ยม | U22: ดีเยี่ยม | V22: ดีเยี่ยม | W22: ดีเยี่ยม | X22: ดีเยี่ยม
A23: 3/30/2026 18:44:51 | B23: หญิง | C23: 18-29 ปี | D23: 169 | E23: 55.5 | F23: 4.4 , 4.03 | G23: มากกว่า 8 ชั่วโมง | H23: มี | I23: ยินยอม | J23: ดีเยี่ยม | K23: ดีเยี่ยม | L23: ดี | M23: ดี | N23: ปานกลาง | O23: ดีเยี่ยม | P23: ดี | Q23: ดีเยี่ยม | R23: ดีเยี่ยม | S23: ดีเยี่ยม | T23: ดีเยี่ยม | U23: ดีเยี่ยม | V23: ดีเยี่ยม | W23: ดีเยี่ยม | X23: ดีเยี่ยม
A24: 3/30/2026 18:46:59 | B24: หญิง | C24: 18-29 ปี | D24: 169.5 | E24: 52 | F24: 5.78 , 0.01 | G24: มากกว่า 8 ชั่วโมง | H24: มี | I24: ยินยอม | J24: ดีเยี่ยม | K24: ดีเยี่ยม | L24: ดีเยี่ยม | M24: ดีเยี่ยม | N24: ดีเยี่ยม | O24: ดีเยี่ยม | P24: ปานกลาง | Q24: ดีเยี่ยม | R24: ดีเยี่ยม | S24: ดีเยี่ยม | T24: ดีเยี่ยม | U24: ดีเยี่ยม | V24: ดีเยี่ยม | W24: ดีเยี่ยม | X24: ดีเยี่ยม
A25: 3/30/2026 20:06:49 | B25: หญิง | C25: 18-29 ปี | D25: 165 | E25: 54 | F25: 0,0 | G25: 4 - 8 ชั่วโมง | H25: มี | I25: ยินยอม | J25: ดี | K25: ดี | L25: ปานกลาง | M25: ดีเยี่ยม | N25: ดี | O25: ดีเยี่ยม | P25: ดีเยี่ยม | Q25: ดีเยี่ยม | R25: ดีเยี่ยม | S25: ดีเยี่ยม | T25: ดีเยี่ยม | U25: ดีเยี่ยม | V25: ดีเยี่ยม | W25: ดีเยี่ยม | X25: ดี | Y25: การใส่ค่อนข้างยาก
A26: 3/30/2026 21:14:07 | B26: หญิง | C26: 18-29 ปี | D26: 164 | E26: 55 | F26: 59.7,-2.5 | G26: มากกว่า 8 ชั่วโมง | H26: เป็นบางครั้งบางคราว | I26: ยินยอม | J26: ดี | K26: ดี | L26: ดี | M26: ดี | N26: ดี | O26: ดีเยี่ยม | P26: ดีเยี่ยม | Q26: ดีเยี่ยม | R26: ดีเยี่ยม | S26: ดีเยี่ยม | T26: ดี | U26: ดีเยี่ยม | V26: ดีเยี่ยม | W26: ดีเยี่ยม | X26: ดี

Sheet total
A2: Hardware | B2: ค่ามัธยฐาน | C2: ระดับ | G2: ค่าเฉลี่ย | H2: ระดับ
A3: 1. ขนาดและน้ำหนักของอุปกรณ์มีความกะทัดรัด ไม่เกะกะ | B3: =score1!C32 -> 4 | C3: =IF(B3>=4.51,"ดีเยี่ยม", IF(B3>=3.51,"ดี", IF(B3>=2.51,"ปานกลาง", IF(B3>=1.51,"น้อย","ปรับปรุง")))) -> ดี | G3: 4.51-5.00 | H3: ดีเยี่ยม
A4: 2. อุปกรณ์สามารถสวมใส่ หรือติดตั้งใช้งานได้ง่าย ไม่ซับซ้อน | B4: =score1!C64 -> 4 | C4: =IF(B4>=4.51,"ดีเยี่ยม", IF(B4>=3.51,"ดี", IF(B4>=2.51,"ปานกลาง", IF(B4>=1.51,"น้อย","ปรับปรุง")))) -> ดี | G4: 3.51-4.50 | H4: ดี
A5: 3. ความรู้สึกสบายเมื่อต้องใช้งานอุปกรณ์ติดต่อกันเป็นเวลานาน | B5: =score1!H32 -> 4 | C5: =IF(B5>=4.51,"ดีเยี่ยม", IF(B5>=3.51,"ดี", IF(B5>=2.51,"ปานกลาง", IF(B5>=1.51,"น้อย","ปรับปรุง")))) -> ดี | G5: 2.51-3.50 | H5: ปานกลาง
A6: 4. อุปกรณ์ไม่ก่อให้เกิดความร้อนจนรบกวนการใช้งาน | B6: =score1!H64 -> 5 | C6: =IF(B6>=4.51,"ดีเยี่ยม", IF(B6>=3.51,"ดี", IF(B6>=2.51,"ปานกลาง", IF(B6>=1.51,"น้อย","ปรับปรุง")))) -> ดีเยี่ยม | G6: 1.51-2.50 | H6: น้อย
A7: 5. ความทนทานและรูปแบบการจัดเก็บสายไฟ/ตัวบอร์ด ดูปลอดภัยและเรียบร้อย | B7: =score1!M32 -> 5 | C7: =IF(B7>=4.51,"ดีเยี่ยม", IF(B7>=3.51,"ดี", IF(B7>=2.51,"ปานกลาง", IF(B7>=1.51,"น้อย","ปรับปรุง")))) -> ดีเยี่ยม | G7: 1.00-1.50 | H7: ปรับปรุง
A8: ค่าเฉลี่ยรวม | B8: =MEDIAN(B3:B7) -> 4 | C8: =IF(B8>=4.51,"ดีเยี่ยม", IF(B8>=3.51,"ดี", IF(B8>=2.51,"ปานกลาง", IF(B8>=1.51,"น้อย","ปรับปรุง")))) -> ดี
A9: Application
A10: 1. การออกแบบหน้าจอแอปพลิเคชัน (UI) มีความสวยงาม ทันสมัย | B10: =score2!C32 -> 5 | C10: =IF(B10>=4.51,"ดีเยี่ยม", IF(B10>=3.51,"ดี", IF(B10>=2.51,"ปานกลาง", IF(B10>=1.51,"น้อย","ปรับปรุง")))) -> ดีเยี่ยม
A11: 2. ความรวดเร็วของการคำนวณและแสดงผลคะแนนรวมของการนั่ง | B11: =score2!C64 -> 5 | C11: =IF(B11>=4.51,"ดีเยี่ยม", IF(B11>=3.51,"ดี", IF(B11>=2.51,"ปานกลาง", IF(B11>=1.51,"น้อย","ปรับปรุง")))) -> ดีเยี่ยม
A12: 3. หน้าแสดงประวัติ (History) และการสรุปข้อมูล | B12: =score2!H32 -> 5 | C12: =IF(B12>=4.51,"ดีเยี่ยม", IF(B12>=3.51,"ดี", IF(B12>=2.51,"ปานกลาง", IF(B12>=1.51,"น้อย","ปรับปรุง")))) -> ดีเยี่ยม
A13: 4. ข้อความคำแนะนำ (Advice) มีความเหมาะสม เข้าใจง่าย และน่าสนใจ | B13: =score2!H64 -> 5 | C13: =IF(B13>=4.51,"ดีเยี่ยม", IF(B13>=3.51,"ดี", IF(B13>=2.51,"ปานกลาง", IF(B13>=1.51,"น้อย","ปรับปรุง")))) -> ดีเยี่ยม
A14: 5. ระดับภาษาที่ระบบใช้แจ้งเตือน (ชมเชย, แนะนำ, ตักเตือน) ช่วยสร้างแรงจูงใจได้ดี | B14: =score2!M32 -> 5 | C14: =IF(B14>=4.51,"ดีเยี่ยม", IF(B14>=3.51,"ดี", IF(B14>=2.51,"ปานกลาง", IF(B14>=1.51,"น้อย","ปรับปรุง")))) -> ดีเยี่ยม
A15: ค่าเฉลี่ยรวม | B15: =MEDIAN(B10:B14) -> 5 | C15: =IF(B15>=4.51,"ดีเยี่ยม", IF(B15>=3.51,"ดี", IF(B15>=2.51,"ปานกลาง", IF(B15>=1.51,"น้อย","ปรับปรุง")))) -> ดีเยี่ยม
A16: Health
A17: 1. ระบบนี้ช่วยให้คุณตระหนักรู้ (Awareness) ถึงท่านั่งที่ผิดปกติของตนเองได้เร็วขึ้น | B17: =score3!C32 -> 5 | C17: =IF(B17>=4.51,"ดีเยี่ยม", IF(B17>=3.51,"ดี", IF(B17>=2.51,"ปานกลาง", IF(B17>=1.51,"น้อย","ปรับปรุง")))) -> ดีเยี่ยม
A18: 2. ข้อความแจ้งเตือนช่วยกระตุ้นให้คุณอยากปรับเปลี่ยนท่านั่งให้ถูกต้อง | B18: =score3!C64 -> 5 | C18: =IF(B18>=4.51,"ดีเยี่ยม", IF(B18>=3.51,"ดี", IF(B18>=2.51,"ปานกลาง", IF(B18>=1.51,"น้อย","ปรับปรุง")))) -> ดีเยี่ยม
A19: 3. หากใช้งานเป็นประจำ คุณเชื่อว่าระบบนี้จะช่วยลดอาการปวดหลัง/ออฟฟิศซินโดรมได้ | B19: =score3!H32 -> 5 | C19: =IF(B19>=4.51,"ดีเยี่ยม", IF(B19>=3.51,"ดี", IF(B19>=2.51,"ปานกลาง", IF(B19>=1.51,"น้อย","ปรับปรุง")))) -> ดีเยี่ยม
A20: 4. ความเหมาะสมของระบบนี้ในการนำไปใช้จริงในชีวิตประจำวัน (เวลาทำงาน/เรียน) | B20: =score3!H64 -> 5 | C20: =IF(B20>=4.51,"ดีเยี่ยม", IF(B20>=3.51,"ดี", IF(B20>=2.51,"ปานกลาง", IF(B20>=1.51,"น้อย","ปรับปรุง")))) -> ดีเยี่ยม
A21: 5. ความพึงพอใจในภาพรวม | B21: =score3!M32 -> 5 | C21: =IF(B21>=4.51,"ดีเยี่ยม", IF(B21>=3.51,"ดี", IF(B21>=2.51,"ปานกลาง", IF(B21>=1.51,"น้อย","ปรับปรุง")))) -> ดีเยี่ยม
A22: ค่ามัธยฐาน | B22: =MEDIAN(B17:B21) -> 5 | C22: =IF(B22>=4.51,"ดีเยี่ยม", IF(B22>=3.51,"ดี", IF(B22>=2.51,"ปานกลาง", IF(B22>=1.51,"น้อย","ปรับปรุง")))) -> ดีเยี่ยม

Sheet Sheet1
A1: หัวข้อผลการประเมิน | B1: ค่ามัธยฐาน | C1: ระดับ
A2: ด้านอุปกรณ์ฮาร์ดแวร์ | B2: =total!B8 -> 4 | C2: =total!C8 -> ดี
A3: ด้านแอปพลิเคชันและการแสดงผล | B3: =total!B15 -> 5 | C3: =total!C15 -> ดีเยี่ยม
A4: ด้านประโยชน์ต่อสุขภาพและการนำไปใช้งานจริง | B4: =total!B22 -> 5 | C4: =total!C22 -> ดีเยี่ยม

Sheet score1
A1: ข้อที่ | B1: จำนวนคน | C1: คะแนน | F1: ข้อที่ | G1: จำนวนคน | H1: คะแนน | K1: ข้อที่ | L1: จำนวนคน | M1: คะแนน
A2: 1 | B2: คนที่ 1 | C2: =IF('Form Responses 1'!J2="ดีเยี่ยม",5, IF('Form Responses 1'!J2="ดี",4, IF('Form Responses 1'!J2="ปานกลาง",3, IF('Form Responses 1'!J2="น้อย",2, IF('Form Responses 1'!J2="ปรับปรุง",1))))) -> 5 | F2: 3 | G2: คนที่ 1 | H2: =IF('Form Responses 1'!L2="ดีเยี่ยม",5, IF('Form Responses 1'!L2="ดี",4, IF('Form Responses 1'!L2="ปานกลาง",3, IF('Form Responses 1'!L2="น้อย",2, IF('Form Responses 1'!L2="ปรับปรุง",1))))) -> 4 | K2: 5 | L2: คนที่ 1 | M2: =IF('Form Responses 1'!N2="ดีเยี่ยม",5, IF('Form Responses 1'!N2="ดี",4, IF('Form Responses 1'!N2="ปานกลาง",3, IF('Form Responses 1'!N2="น้อย",2, IF('Form Responses 1'!N2="ปรับปรุง",1))))) -> 5
B3: คนที่ 2 | C3: =IF('Form Responses 1'!K3="ดีเยี่ยม",5, IF('Form Responses 1'!K3="ดี",4, IF('Form Responses 1'!K3="ปานกลาง",3, IF('Form Responses 1'!K3="น้อย",2, IF('Form Responses 1'!K3="ปรับปรุง",1))))) -> 4 | G3: คนที่ 2 | H3: =IF('Form Responses 1'!L3="ดีเยี่ยม",5, IF('Form Responses 1'!L3="ดี",4, IF('Form Responses 1'!L3="ปานกลาง",3, IF('Form Responses 1'!L3="น้อย",2, IF('Form Responses 1'!L3="ปรับปรุง",1))))) -> 5 | L3: คนที่ 2 | M3: =IF('Form Responses 1'!N3="ดีเยี่ยม",5, IF('Form Responses 1'!N3="ดี",4, IF('Form Responses 1'!N3="ปานกลาง",3, IF('Form Responses 1'!N3="น้อย",2, IF('Form Responses 1'!N3="ปรับปรุง",1))))) -> 5
B4: คนที่ 3 | C4: =IF('Form Responses 1'!K4="ดีเยี่ยม",5, IF('Form Responses 1'!K4="ดี",4, IF('Form Responses 1'!K4="ปานกลาง",3, IF('Form Responses 1'!K4="น้อย",2, IF('Form Responses 1'!K4="ปรับปรุง",1))))) -> 4 | G4: คนที่ 3 | H4: =IF('Form Responses 1'!L4="ดีเยี่ยม",5, IF('Form Responses 1'!L4="ดี",4, IF('Form Responses 1'!L4="ปานกลาง",3, IF('Form Responses 1'!L4="น้อย",2, IF('Form Responses 1'!L4="ปรับปรุง",1))))) -> 3 | L4: คนที่ 3 | M4: =IF('Form Responses 1'!N4="ดีเยี่ยม",5, IF('Form Responses 1'!N4="ดี",4, IF('Form Responses 1'!N4="ปานกลาง",3, IF('Form Responses 1'!N4="น้อย",2, IF('Form Responses 1'!N4="ปรับปรุง",1))))) -> 5
B5: คนที่ 4 | C5: =IF('Form Responses 1'!K5="ดีเยี่ยม",5, IF('Form Responses 1'!K5="ดี",4, IF('Form Responses 1'!K5="ปานกลาง",3, IF('Form Responses 1'!K5="น้อย",2, IF('Form Responses 1'!K5="ปรับปรุง",1))))) -> 4 | G5: คนที่ 4 | H5: =IF('Form Responses 1'!L5="ดีเยี่ยม",5, IF('Form Responses 1'!L5="ดี",4, IF('Form Responses 1'!L5="ปานกลาง",3, IF('Form Responses 1'!L5="น้อย",2, IF('Form Responses 1'!L5="ปรับปรุง",1))))) -> 3 | L5: คนที่ 4 | M5: =IF('Form Responses 1'!N5="ดีเยี่ยม",5, IF('Form Responses 1'!N5="ดี",4, IF('Form Responses 1'!N5="ปานกลาง",3, IF('Form Responses 1'!N5="น้อย",2, IF('Form Responses 1'!N5="ปรับปรุง",1))))) -> 3
B6: คนที่ 5 | C6: =IF('Form Responses 1'!K6="ดีเยี่ยม",5, IF('Form Responses 1'!K6="ดี",4, IF('Form Responses 1'!K6="ปานกลาง",3, IF('Form Responses 1'!K6="น้อย",2, IF('Form Responses 1'!K6="ปรับปรุง",1))))) -> 5 | G6: คนที่ 5 | H6: =IF('Form Responses 1'!L6="ดีเยี่ยม",5, IF('Form Responses 1'!L6="ดี",4, IF('Form Responses 1'!L6="ปานกลาง",3, IF('Form Responses 1'!L6="น้อย",2, IF('Form Responses 1'!L6="ปรับปรุง",1))))) -> 4 | L6: คนที่ 5 | M6: =IF('Form Responses 1'!N6="ดีเยี่ยม",5, IF('Form Responses 1'!N6="ดี",4, IF('Form Responses 1'!N6="ปานกลาง",3, IF('Form Responses 1'!N6="น้อย",2, IF('Form Responses 1'!N6="ปรับปรุง",1))))) -> 5
B7: คนที่ 6 | C7: =IF('Form Responses 1'!K7="ดีเยี่ยม",5, IF('Form Responses 1'!K7="ดี",4, IF('Form Responses 1'!K7="ปานกลาง",3, IF('Form Responses 1'!K7="น้อย",2, IF('Form Responses 1'!K7="ปรับปรุง",1))))) -> 4 | G7: คนที่ 6 | H7: =IF('Form Responses 1'!L7="ดีเยี่ยม",5, IF('Form Responses 1'!L7="ดี",4, IF('Form Responses 1'!L7="ปานกลาง",3, IF('Form Responses 1'!L7="น้อย",2, IF('Form Responses 1'!L7="ปรับปรุง",1))))) -> 4 | L7: คนที่ 6 | M7: =IF('Form Responses 1'!N7="ดีเยี่ยม",5, IF('Form Responses 1'!N7="ดี",4, IF('Form Responses 1'!N7="ปานกลาง",3, IF('Form Responses 1'!N7="น้อย",2, IF('Form Responses 1'!N7="ปรับปรุง",1))))) -> 4
B8: คนที่ 7 | C8: =IF('Form Responses 1'!K8="ดีเยี่ยม",5, IF('Form Responses 1'!K8="ดี",4, IF('Form Responses 1'!K8="ปานกลาง",3, IF('Form Responses 1'!K8="น้อย",2, IF('Form Responses 1'!K8="ปรับปรุง",1))))) -> 3 | G8: คนที่ 7 | H8: =IF('Form Responses 1'!L8="ดีเยี่ยม",5, IF('Form Responses 1'!L8="ดี",4, IF('Form Responses 1'!L8="ปานกลาง",3, IF('Form Responses 1'!L8="น้อย",2, IF('Form Responses 1'!L8="ปรับปรุง",1))))) -> 4 | L8: คนที่ 7 | M8: =IF('Form Responses 1'!N8="ดีเยี่ยม",5, IF('Form Responses 1'!N8="ดี",4, IF('Form Responses 1'!N8="ปานกลาง",3, IF('Form Responses 1'!N8="น้อย",2, IF('Form Responses 1'!N8="ปรับปรุง",1))))) -> 5
B9: คนที่ 8 | C9: =IF('Form Responses 1'!K9="ดีเยี่ยม",5, IF('Form Responses 1'!K9="ดี",4, IF('Form Responses 1'!K9="ปานกลาง",3, IF('Form Responses 1'!K9="น้อย",2, IF('Form Responses 1'!K9="ปรับปรุง",1))))) -> 4 | G9: คนที่ 8 | H9: =IF('Form Responses 1'!L9="ดีเยี่ยม",5, IF('Form Responses 1'!L9="ดี",4, IF('Form Responses 1'!L9="ปานกลาง",3, IF('Form Responses 1'!L9="น้อย",2, IF('Form Responses 1'!L9="ปรับปรุง",1))))) -> 5 | L9: คนที่ 8 | M9: =IF('Form Responses 1'!N9="ดีเยี่ยม",5, IF('Form Responses 1'!N9="ดี",4, IF('Form Responses 1'!N9="ปานกลาง",3, IF('Form Responses 1'!N9="น้อย",2, IF('Form Responses 1'!N9="ปรับปรุง",1))))) -> 5
B10: คนที่ 9 | C10: =IF('Form Responses 1'!K10="ดีเยี่ยม",5, IF('Form Responses 1'!K10="ดี",4, IF('Form Responses 1'!K10="ปานกลาง",3, IF('Form Responses 1'!K10="น้อย",2, IF('Form Responses 1'!K10="ปรับปรุง",1))))) -> 4 | G10: คนที่ 9 | H10: =IF('Form Responses 1'!L10="ดีเยี่ยม",5, IF('Form Responses 1'!L10="ดี",4, IF('Form Responses 1'!L10="ปานกลาง",3, IF('Form Responses 1'!L10="น้อย",2, IF('Form Responses 1'!L10="ปรับปรุง",1))))) -> 4 | L10: คนที่ 9 | M10: =IF('Form Responses 1'!N10="ดีเยี่ยม",5, IF('Form Responses 1'!N10="ดี",4, IF('Form Responses 1'!N10="ปานกลาง",3, IF('Form Responses 1'!N10="น้อย",2, IF('Form Responses 1'!N10="ปรับปรุง",1))))) -> 5
B11: คนที่ 10 | C11: =IF('Form Responses 1'!K11="ดีเยี่ยม",5, IF('Form Responses 1'!K11="ดี",4, IF('Form Responses 1'!K11="ปานกลาง",3, IF('Form Responses 1'!K11="น้อย",2, IF('Form Responses 1'!K11="ปรับปรุง",1))))) -> 4 | G11: คนที่ 10 | H11: =IF('Form Responses 1'!L11="ดีเยี่ยม",5, IF('Form Responses 1'!L11="ดี",4, IF('Form Responses 1'!L11="ปานกลาง",3, IF('Form Responses 1'!L11="น้อย",2, IF('Form Responses 1'!L11="ปรับปรุง",1))))) -> 5 | L11: คนที่ 10 | M11: =IF('Form Responses 1'!N11="ดีเยี่ยม",5, IF('Form Responses 1'!N11="ดี",4, IF('Form Responses 1'!N11="ปานกลาง",3, IF('Form Responses 1'!N11="น้อย",2, IF('Form Responses 1'!N11="ปรับปรุง",1))))) -> 5
B12: คนที่ 11 | C12: =IF('Form Responses 1'!K12="ดีเยี่ยม",5, IF('Form Responses 1'!K12="ดี",4, IF('Form Responses 1'!K12="ปานกลาง",3, IF('Form Responses 1'!K12="น้อย",2, IF('Form Responses 1'!K12="ปรับปรุง",1))))) -> 5 | G12: คนที่ 11 | H12: =IF('Form Responses 1'!L12="ดีเยี่ยม",5, IF('Form Responses 1'!L12="ดี",4, IF('Form Responses 1'!L12="ปานกลาง",3, IF('Form Responses 1'!L12="น้อย",2, IF('Form Responses 1'!L12="ปรับปรุง",1))))) -> 5 | L12: คนที่ 11 | M12: =IF('Form Responses 1'!N12="ดีเยี่ยม",5, IF('Form Responses 1'!N12="ดี",4, IF('Form Responses 1'!N12="ปานกลาง",3, IF('Form Responses 1'!N12="น้อย",2, IF('Form Responses 1'!N12="ปรับปรุง",1))))) -> 5
B13: คนที่ 12 | C13: =IF('Form Responses 1'!K13="ดีเยี่ยม",5, IF('Form Responses 1'!K13="ดี",4, IF('Form Responses 1'!K13="ปานกลาง",3, IF('Form Responses 1'!K13="น้อย",2, IF('Form Responses 1'!K13="ปรับปรุง",1))))) -> 5 | G13: คนที่ 12 | H13: =IF('Form Responses 1'!L13="ดีเยี่ยม",5, IF('Form Responses 1'!L13="ดี",4, IF('Form Responses 1'!L13="ปานกลาง",3, IF('Form Responses 1'!L13="น้อย",2, IF('Form Responses 1'!L13="ปรับปรุง",1))))) -> 3 | L13: คนที่ 12 | M13: =IF('Form Responses 1'!N13="ดีเยี่ยม",5, IF('Form Responses 1'!N13="ดี",4, IF('Form Responses 1'!N13="ปานกลาง",3, IF('Form Responses 1'!N13="น้อย",2, IF('Form Responses 1'!N13="ปรับปรุง",1))))) -> 4
B14: คนที่ 13 | C14: =IF('Form Responses 1'!K14="ดีเยี่ยม",5, IF('Form Responses 1'!K14="ดี",4, IF('Form Responses 1'!K14="ปานกลาง",3, IF('Form Responses 1'!K14="น้อย",2, IF('Form Responses 1'!K14="ปรับปรุง",1))))) -> 4 | G14: คนที่ 13 | H14: =IF('Form Responses 1'!L14="ดีเยี่ยม",5, IF('Form Responses 1'!L14="ดี",4, IF('Form Responses 1'!L14="ปานกลาง",3, IF('Form Responses 1'!L14="น้อย",2, IF('Form Responses 1'!L14="ปรับปรุง",1))))) -> 4 | L14: คนที่ 13 | M14: =IF('Form Responses 1'!N14="ดีเยี่ยม",5, IF('Form Responses 1'!N14="ดี",4, IF('Form Responses 1'!N14="ปานกลาง",3, IF('Form Responses 1'!N14="น้อย",2, IF('Form Responses 1'!N14="ปรับปรุง",1))))) -> 4
... B26: คนที่ 25 | C26: =IF('Form Responses 1'!K26="ดีเยี่ยม",5, IF('Form Responses 1'!K26="ดี",4, IF('Form Responses 1'!K26="ปานกลาง",3, IF('Form Responses 1'!K26="น้อย",2, IF('Form Responses 1'!K26="ปรับปรุง",1))))) -> 4 | G26: คนที่ 25 | H26: =IF('Form Responses 1'!L26="ดีเยี่ยม",5, IF('Form Responses 1'!L26="ดี",4, IF('Form Responses 1'!L26="ปานกลาง",3, IF('Form Responses 1'!L26="น้อย",2, IF('Form Responses 1'!L26="ปรับปรุง",1))))) -> 4 | L26: คนที่ 25 | M26: =IF('Form Responses 1'!N26="ดีเยี่ยม",5, IF('Form Responses 1'!N26="ดี",4, IF('Form Responses 1'!N26="ปานกลาง",3, IF('Form Responses 1'!N26="น้อย",2, IF('Form Responses 1'!N26="ปรับปรุง",1))))) -> 4
A32: ค่าเฉลี่ย | C32: =MEDIAN(C2:C31) -> 4 | F32: ค่าเฉลี่ย | H32: =MEDIAN(H2:H31) -> 4 | K32: ค่าเฉลี่ย | M32: =MEDIAN(M2:M31) -> 5
A34: 2 | B34: คนที่ 1 | C34: =IF('Form Responses 1'!K2="ดีเยี่ยม",5, IF('Form Responses 1'!K2="ดี",4, IF('Form Responses 1'!K2="ปานกลาง",3, IF('Form Responses 1'!K2="น้อย",2, IF('Form Responses 1'!K2="ปรับปรุง",1))))) -> 3 | F34: 4 | G34: คนที่ 1 | H34: =IF('Form Responses 1'!M2="ดีเยี่ยม",5, IF('Form Responses 1'!M2="ดี",4, IF('Form Responses 1'!M2="ปานกลาง",3, IF('Form Responses 1'!M2="น้อย",2, IF('Form Responses 1'!M2="ปรับปรุง",1))))) -> 5
B35: คนที่ 2 | C35: =IF('Form Responses 1'!K3="ดีเยี่ยม",5, IF('Form Responses 1'!K3="ดี",4, IF('Form Responses 1'!K3="ปานกลาง",3, IF('Form Responses 1'!K3="น้อย",2, IF('Form Responses 1'!K3="ปรับปรุง",1))))) -> 4 | G35: คนที่ 2 | H35: =IF('Form Responses 1'!M3="ดีเยี่ยม",5, IF('Form Responses 1'!M3="ดี",4, IF('Form Responses 1'!M3="ปานกลาง",3, IF('Form Responses 1'!M3="น้อย",2, IF('Form Responses 1'!M3="ปรับปรุง",1))))) -> 5
B36: คนที่ 3 | C36: =IF('Form Responses 1'!K4="ดีเยี่ยม",5, IF('Form Responses 1'!K4="ดี",4, IF('Form Responses 1'!K4="ปานกลาง",3, IF('Form Responses 1'!K4="น้อย",2, IF('Form Responses 1'!K4="ปรับปรุง",1))))) -> 4 | G36: คนที่ 3 | H36: =IF('Form Responses 1'!M4="ดีเยี่ยม",5, IF('Form Responses 1'!M4="ดี",4, IF('Form Responses 1'!M4="ปานกลาง",3, IF('Form Responses 1'!M4="น้อย",2, IF('Form Responses 1'!M4="ปรับปรุง",1))))) -> 5
B37: คนที่ 4 | C37: =IF('Form Responses 1'!K5="ดีเยี่ยม",5, IF('Form Responses 1'!K5="ดี",4, IF('Form Responses 1'!K5="ปานกลาง",3, IF('Form Responses 1'!K5="น้อย",2, IF('Form Responses 1'!K5="ปรับปรุง",1))))) -> 4 | G37: คนที่ 4 | H37: =IF('Form Responses 1'!M5="ดีเยี่ยม",5, IF('Form Responses 1'!M5="ดี",4, IF('Form Responses 1'!M5="ปานกลาง",3, IF('Form Responses 1'!M5="น้อย",2, IF('Form Responses 1'!M5="ปรับปรุง",1))))) -> 3
B38: คนที่ 5 | C38: =IF('Form Responses 1'!K6="ดีเยี่ยม",5, IF('Form Responses 1'!K6="ดี",4, IF('Form Responses 1'!K6="ปานกลาง",3, IF('Form Responses 1'!K6="น้อย",2, IF('Form Responses 1'!K6="ปรับปรุง",1))))) -> 5 | G38: คนที่ 5 | H38: =IF('Form Responses 1'!M6="ดีเยี่ยม",5, IF('Form Responses 1'!M6="ดี",4, IF('Form Responses 1'!M6="ปานกลาง",3, IF('Form Responses 1'!M6="น้อย",2, IF('Form Responses 1'!M6="ปรับปรุง",1))))) -> 5
B39: คนที่ 6 | C39: =IF('Form Responses 1'!K7="ดีเยี่ยม",5, IF('Form Responses 1'!K7="ดี",4, IF('Form Responses 1'!K7="ปานกลาง",3, IF('Form Responses 1'!K7="น้อย",2, IF('Form Responses 1'!K7="ปรับปรุง",1))))) -> 4 | G39: คนที่ 6 | H39: =IF('Form Responses 1'!M7="ดีเยี่ยม",5, IF('Form Responses 1'!M7="ดี",4, IF('Form Responses 1'!M7="ปานกลาง",3, IF('Form Responses 1'!M7="น้อย",2, IF('Form Responses 1'!M7="ปรับปรุง",1))))) -> 5
B40: คนที่ 7 | C40: =IF('Form Responses 1'!K8="ดีเยี่ยม",5, IF('Form Responses 1'!K8="ดี",4, IF('Form Responses 1'!K8="ปานกลาง",3, IF('Form Responses 1'!K8="น้อย",2, IF('Form Responses 1'!K8="ปรับปรุง",1))))) -> 3 | G40: คนที่ 7 | H40: =IF('Form Responses 1'!M8="ดีเยี่ยม",5, IF('Form Responses 1'!M8="ดี",4, IF('Form Responses 1'!M8="ปานกลาง",3, IF('Form Responses 1'!M8="น้อย",2, IF('Form Responses 1'!M8="ปรับปรุง",1))))) -> 5
B41: คนที่ 8 | C41: =IF('Form Responses 1'!K9="ดีเยี่ยม",5, IF('Form Responses 1'!K9="ดี",4, IF('Form Responses 1'!K9="ปานกลาง",3, IF('Form Responses 1'!K9="น้อย",2, IF('Form Responses 1'!K9="ปรับปรุง",1))))) -> 4 | G41: คนที่ 8 | H41: =IF('Form Responses 1'!M9="ดีเยี่ยม",5, IF('Form Responses 1'!M9="ดี",4, IF('Form Responses 1'!M9="ปานกลาง",3, IF('Form Responses 1'!M9="น้อย",2, IF('Form Responses 1'!M9="ปรับปรุง",1))))) -> 5
B42: คนที่ 9 | C42: =IF('Form Responses 1'!K10="ดีเยี่ยม",5, IF('Form Responses 1'!K10="ดี",4, IF('Form Responses 1'!K10="ปานกลาง",3, IF('Form Responses 1'!K10="น้อย",2, IF('Form Responses 1'!K10="ปรับปรุง",1))))) -> 4 | G42: คนที่ 9 | H42: =IF('Form Responses 1'!M10="ดีเยี่ยม",5, IF('Form Responses 1'!M10="ดี",4, IF('Form Responses 1'!M10="ปานกลาง",3, IF('Form Responses 1'!M10="น้อย",2, IF('Form Responses 1'!M10="ปรับปรุง",1))))) -> 5
B43: คนที่ 10 | C43: =IF('Form Responses 1'!K11="ดีเยี่ยม",5, IF('Form Responses 1'!K11="ดี",4, IF('Form Responses 1'!K11="ปานกลาง",3, IF('Form Responses 1'!K11="น้อย",2, IF('Form Responses 1'!K11="ปรับปรุง",1))))) -> 4 | G43: คนที่ 10 | H43: =IF('Form Responses 1'!M11="ดีเยี่ยม",5, IF('Form Responses 1'!M11="ดี",4, IF('Form Responses 1'!M11="ปานกลาง",3, IF('Form Responses 1'!M11="น้อย",2, IF('Form Responses 1'!M11="ปรับปรุง",1))))) -> 5
B44: คนที่ 11 | C44: =IF('Form Responses 1'!K12="ดีเยี่ยม",5, IF('Form Responses 1'!K12="ดี",4, IF('Form Responses 1'!K12="ปานกลาง",3, IF('Form Responses 1'!K12="น้อย",2, IF('Form Responses 1'!K12="ปรับปรุง",1))))) -> 5 | G44: คนที่ 11 | H44: =IF('Form Responses 1'!M12="ดีเยี่ยม",5, IF('Form Responses 1'!M12="ดี",4, IF('Form Responses 1'!M12="ปานกลาง",3, IF('Form Responses 1'!M12="น้อย",2, IF('Form Responses 1'!M12="ปรับปรุง",1))))) -> 5
B45: คนที่ 12 | C45: =IF('Form Responses 1'!K13="ดีเยี่ยม",5, IF('Form Responses 1'!K13="ดี",4, IF('Form Responses 1'!K13="ปานกลาง",3, IF('Form Responses 1'!K13="น้อย",2, IF('Form Responses 1'!K13="ปรับปรุง",1))))) -> 5 | G45: คนที่ 12 | H45: =IF('Form Responses 1'!M13="ดีเยี่ยม",5, IF('Form Responses 1'!M13="ดี",4, IF('Form Responses 1'!M13="ปานกลาง",3, IF('Form Responses 1'!M13="น้อย",2, IF('Form Responses 1'!M13="ปรับปรุง",1))))) -> 5
B46: คนที่ 13 | C46: =IF('Form Responses 1'!K14="ดีเยี่ยม",5, IF('Form Responses 1'!K14="ดี",4, IF('Form Responses 1'!K14="ปานกลาง",3, IF('Form Responses 1'!K14="น้อย",2, IF('Form Responses 1'!K14="ปรับปรุง",1))))) -> 4 | G46: คนที่ 13 | H46: =IF('Form Responses 1'!M14="ดีเยี่ยม",5, IF('Form Responses 1'!M14="ดี",4, IF('Form Responses 1'!M14="ปานกลาง",3, IF('Form Responses 1'!M14="น้อย",2, IF('Form Responses 1'!M14="ปรับปรุง",1))))) -> 5
... B58: คนที่ 25 | C58: =IF('Form Responses 1'!K26="ดีเยี่ยม",5, IF('Form Responses 1'!K26="ดี",4, IF('Form Responses 1'!K26="ปานกลาง",3, IF('Form Responses 1'!K26="น้อย",2, IF('Form Responses 1'!K26="ปรับปรุง",1))))) -> 4 | G58: คนที่ 25 | H58: =IF('Form Responses 1'!M26="ดีเยี่ยม",5, IF('Form Responses 1'!M26="ดี",4, IF('Form Responses 1'!M26="ปานกลาง",3, IF('Form Responses 1'!M26="น้อย",2, IF('Form Responses 1'!M26="ปรับปรุง",1))))) -> 4
A64: ค่าเฉลี่ย | C64: =MEDIAN(C34:C63) -> 4 | F64: ค่าเฉลี่ย | H64: =MEDIAN(H34:H63) -> 5

Sheet score2
A1: ข้อที่ | B1: จำนวนคน | C1: คะแนน | F1: ข้อที่ | G1: จำนวนคน | H1: คะแนน | K1: ข้อที่ | L1: จำนวนคน | M1: คะแนน
A2: 1 | B2: คนที่ 1 | C2: =IF('Form Responses 1'!O2="ดีเยี่ยม",5, IF('Form Responses 1'!O2="ดี",4, IF('Form Responses 1'!O2="ปานกลาง",3, IF('Form Responses 1'!O2="น้อย",2, IF('Form Responses 1'!O2="ปรับปรุง",1))))) -> 4 | F2: 3 | G2: คนที่ 1 | H2: =IF('Form Responses 1'!Q2="ดีเยี่ยม",5, IF('Form Responses 1'!Q2="ดี",4, IF('Form Responses 1'!Q2="ปานกลาง",3, IF('Form Responses 1'!Q2="น้อย",2, IF('Form Responses 1'!Q2="ปรับปรุง",1))))) -> 4 | K2: 5 | L2: คนที่ 1 | M2: =IF('Form Responses 1'!S2="ดีเยี่ยม",5, IF('Form Responses 1'!S2="ดี",4, IF('Form Responses 1'!S2="ปานกลาง",3, IF('Form Responses 1'!S2="น้อย",2, IF('Form Responses 1'!S2="ปรับปรุง",1))))) -> 5
B3: คนที่ 2 | C3: =IF('Form Responses 1'!O3="ดีเยี่ยม",5, IF('Form Responses 1'!O3="ดี",4, IF('Form Responses 1'!O3="ปานกลาง",3, IF('Form Responses 1'!O3="น้อย",2, IF('Form Responses 1'!O3="ปรับปรุง",1))))) -> 4 | G3: คนที่ 2 | H3: =IF('Form Responses 1'!Q3="ดีเยี่ยม",5, IF('Form Responses 1'!Q3="ดี",4, IF('Form Responses 1'!Q3="ปานกลาง",3, IF('Form Responses 1'!Q3="น้อย",2, IF('Form Responses 1'!Q3="ปรับปรุง",1))))) -> 5 | L3: คนที่ 2 | M3: =IF('Form Responses 1'!S3="ดีเยี่ยม",5, IF('Form Responses 1'!S3="ดี",4, IF('Form Responses 1'!S3="ปานกลาง",3, IF('Form Responses 1'!S3="น้อย",2, IF('Form Responses 1'!S3="ปรับปรุง",1))))) -> 5
B4: คนที่ 3 | C4: =IF('Form Responses 1'!O4="ดีเยี่ยม",5, IF('Form Responses 1'!O4="ดี",4, IF('Form Responses 1'!O4="ปานกลาง",3, IF('Form Responses 1'!O4="น้อย",2, IF('Form Responses 1'!O4="ปรับปรุง",1))))) -> 5 | G4: คนที่ 3 | H4: =IF('Form Responses 1'!Q4="ดีเยี่ยม",5, IF('Form Responses 1'!Q4="ดี",4, IF('Form Responses 1'!Q4="ปานกลาง",3, IF('Form Responses 1'!Q4="น้อย",2, IF('Form Responses 1'!Q4="ปรับปรุง",1))))) -> 4 | L4: คนที่ 3 | M4: =IF('Form Responses 1'!S4="ดีเยี่ยม",5, IF('Form Responses 1'!S4="ดี",4, IF('Form Responses 1'!S4="ปานกลาง",3, IF('Form Responses 1'!S4="น้อย",2, IF('Form Responses 1'!S4="ปรับปรุง",1))))) -> 5
B5: คนที่ 4 | C5: =IF('Form Responses 1'!O5="ดีเยี่ยม",5, IF('Form Responses 1'!O5="ดี",4, IF('Form Responses 1'!O5="ปานกลาง",3, IF('Form Responses 1'!O5="น้อย",2, IF('Form Responses 1'!O5="ปรับปรุง",1))))) -> 4 | G5: คนที่ 4 | H5: =IF('Form Responses 1'!Q5="ดีเยี่ยม",5, IF('Form Responses 1'!Q5="ดี",4, IF('Form Responses 1'!Q5="ปานกลาง",3, IF('Form Responses 1'!Q5="น้อย",2, IF('Form Responses 1'!Q5="ปรับปรุง",1))))) -> 4 | L5: คนที่ 4 | M5: =IF('Form Responses 1'!S5="ดีเยี่ยม",5, IF('Form Responses 1'!S5="ดี",4, IF('Form Responses 1'!S5="ปานกลาง",3, IF('Form Responses 1'!S5="น้อย",2, IF('Form Responses 1'!S5="ปรับปรุง",1))))) -> 4
B6: คนที่ 5 | C6: =IF('Form Responses 1'!O6="ดีเยี่ยม",5, IF('Form Responses 1'!O6="ดี",4, IF('Form Responses 1'!O6="ปานกลาง",3, IF('Form Responses 1'!O6="น้อย",2, IF('Form Responses 1'!O6="ปรับปรุง",1))))) -> 5 | G6: คนที่ 5 | H6: =IF('Form Responses 1'!Q6="ดีเยี่ยม",5, IF('Form Responses 1'!Q6="ดี",4, IF('Form Responses 1'!Q6="ปานกลาง",3, IF('Form Responses 1'!Q6="น้อย",2, IF('Form Responses 1'!Q6="ปรับปรุง",1))))) -> 5 | L6: คนที่ 5 | M6: =IF('Form Responses 1'!S6="ดีเยี่ยม",5, IF('Form Responses 1'!S6="ดี",4, IF('Form Responses 1'!S6="ปานกลาง",3, IF('Form Responses 1'!S6="น้อย",2, IF('Form Responses 1'!S6="ปรับปรุง",1))))) -> 5
B7: คนที่ 6 | C7: =IF('Form Responses 1'!O7="ดีเยี่ยม",5, IF('Form Responses 1'!O7="ดี",4, IF('Form Responses 1'!O7="ปานกลาง",3, IF('Form Responses 1'!O7="น้อย",2, IF('Form Responses 1'!O7="ปรับปรุง",1))))) -> 4 | G7: คนที่ 6 | H7: =IF('Form Responses 1'!Q7="ดีเยี่ยม",5, IF('Form Responses 1'!Q7="ดี",4, IF('Form Responses 1'!Q7="ปานกลาง",3, IF('Form Responses 1'!Q7="น้อย",2, IF('Form Responses 1'!Q7="ปรับปรุง",1))))) -> 5 | L7: คนที่ 6 | M7: =IF('Form Responses 1'!S7="ดีเยี่ยม",5, IF('Form Responses 1'!S7="ดี",4, IF('Form Responses 1'!S7="ปานกลาง",3, IF('Form Responses 1'!S7="น้อย",2, IF('Form Responses 1'!S7="ปรับปรุง",1))))) -> 5
B8: คนที่ 7 | C8: =IF('Form Responses 1'!O8="ดีเยี่ยม",5, IF('Form Responses 1'!O8="ดี",4, IF('Form Responses 1'!O8="ปานกลาง",3, IF('Form Responses 1'!O8="น้อย",2, IF('Form Responses 1'!O8="ปรับปรุง",1))))) -> 5 | G8: คนที่ 7 | H8: =IF('Form Responses 1'!Q8="ดีเยี่ยม",5, IF('Form Responses 1'!Q8="ดี",4, IF('Form Responses 1'!Q8="ปานกลาง",3, IF('Form Responses 1'!Q8="น้อย",2, IF('Form Responses 1'!Q8="ปรับปรุง",1))))) -> 5 | L8: คนที่ 7 | M8: =IF('Form Responses 1'!S8="ดีเยี่ยม",5, IF('Form Responses 1'!S8="ดี",4, IF('Form Responses 1'!S8="ปานกลาง",3, IF('Form Responses 1'!S8="น้อย",2, IF('Form Responses 1'!S8="ปรับปรุง",1))))) -> 4
B9: คนที่ 8 | C9: =IF('Form Responses 1'!O9="ดีเยี่ยม",5, IF('Form Responses 1'!O9="ดี",4, IF('Form Responses 1'!O9="ปานกลาง",3, IF('Form Responses 1'!O9="น้อย",2, IF('Form Responses 1'!O9="ปรับปรุง",1))))) -> 5 | G9: คนที่ 8 | H9: =IF('Form Responses 1'!Q9="ดีเยี่ยม",5, IF('Form Responses 1'!Q9="ดี",4, IF('Form Responses 1'!Q9="ปานกลาง",3, IF('Form Responses 1'!Q9="น้อย",2, IF('Form Responses 1'!Q9="ปรับปรุง",1))))) -> 5 | L9: คนที่ 8 | M9: =IF('Form Responses 1'!S9="ดีเยี่ยม",5, IF('Form Responses 1'!S9="ดี",4, IF('Form Responses 1'!S9="ปานกลาง",3, IF('Form Responses 1'!S9="น้อย",2, IF('Form Responses 1'!S9="ปรับปรุง",1))))) -> 4
B10: คนที่ 9 | C10: =IF('Form Responses 1'!O10="ดีเยี่ยม",5, IF('Form Responses 1'!O10="ดี",4, IF('Form Responses 1'!O10="ปานกลาง",3, IF('Form Responses 1'!O10="น้อย",2, IF('Form Responses 1'!O10="ปรับปรุง",1))))) -> 5 | G10: คนที่ 9 | H10: =IF('Form Responses 1'!Q10="ดีเยี่ยม",5, IF('Form Responses 1'!Q10="ดี",4, IF('Form Responses 1'!Q10="ปานกลาง",3, IF('Form Responses 1'!Q10="น้อย",2, IF('Form Responses 1'!Q10="ปรับปรุง",1))))) -> 5 | L10: คนที่ 9 | M10: =IF('Form Responses 1'!S10="ดีเยี่ยม",5, IF('Form Responses 1'!S10="ดี",4, IF('Form Responses 1'!S10="ปานกลาง",3, IF('Form Responses 1'!S10="น้อย",2, IF('Form Responses 1'!S10="ปรับปรุง",1))))) -> 5
B11: คนที่ 10 | C11: =IF('Form Responses 1'!O11="ดีเยี่ยม",5, IF('Form Responses 1'!O11="ดี",4, IF('Form Responses 1'!O11="ปานกลาง",3, IF('Form Responses 1'!O11="น้อย",2, IF('Form Responses 1'!O11="ปรับปรุง",1))))) -> 5 | G11: คนที่ 10 | H11: =IF('Form Responses 1'!Q11="ดีเยี่ยม",5, IF('Form Responses 1'!Q11="ดี",4, IF('Form Responses 1'!Q11="ปานกลาง",3, IF('Form Responses 1'!Q11="น้อย",2, IF('Form Responses 1'!Q11="ปรับปรุง",1))))) -> 5 | L11: คนที่ 10 | M11: =IF('Form Responses 1'!S11="ดีเยี่ยม",5, IF('Form Responses 1'!S11="ดี",4, IF('Form Responses 1'!S11="ปานกลาง",3, IF('Form Responses 1'!S11="น้อย",2, IF('Form Responses 1'!S11="ปรับปรุง",1))))) -> 5
B12: คนที่ 11 | C12: =IF('Form Responses 1'!O12="ดีเยี่ยม",5, IF('Form Responses 1'!O12="ดี",4, IF('Form Responses 1'!O12="ปานกลาง",3, IF('Form Responses 1'!O12="น้อย",2, IF('Form Responses 1'!O12="ปรับปรุง",1))))) -> 5 | G12: คนที่ 11 | H12: =IF('Form Responses 1'!Q12="ดีเยี่ยม",5, IF('Form Responses 1'!Q12="ดี",4, IF('Form Responses 1'!Q12="ปานกลาง",3, IF('Form Responses 1'!Q12="น้อย",2, IF('Form Responses 1'!Q12="ปรับปรุง",1))))) -> 5 | L12: คนที่ 11 | M12: =IF('Form Responses 1'!S12="ดีเยี่ยม",5, IF('Form Responses 1'!S12="ดี",4, IF('Form Responses 1'!S12="ปานกลาง",3, IF('Form Responses 1'!S12="น้อย",2, IF('Form Responses 1'!S12="ปรับปรุง",1))))) -> 5
B13: คนที่ 12 | C13: =IF('Form Responses 1'!O13="ดีเยี่ยม",5, IF('Form Responses 1'!O13="ดี",4, IF('Form Responses 1'!O13="ปานกลาง",3, IF('Form Responses 1'!O13="น้อย",2, IF('Form Responses 1'!O13="ปรับปรุง",1))))) -> 4 | G13: คนที่ 12 | H13: =IF('Form Responses 1'!Q13="ดีเยี่ยม",5, IF('Form Responses 1'!Q13="ดี",4, IF('Form Responses 1'!Q13="ปานกลาง",3, IF('Form Responses 1'!Q13="น้อย",2, IF('Form Responses 1'!Q13="ปรับปรุง",1))))) -> 5 | L13: คนที่ 12 | M13: =IF('Form Responses 1'!S13="ดีเยี่ยม",5, IF('Form Responses 1'!S13="ดี",4, IF('Form Responses 1'!S13="ปานกลาง",3, IF('Form Responses 1'!S13="น้อย",2, IF('Form Responses 1'!S13="ปรับปรุง",1))))) -> 5
B14: คนที่ 13 | C14: =IF('Form Responses 1'!O14="ดีเยี่ยม",5, IF('Form Responses 1'!O14="ดี",4, IF('Form Responses 1'!O14="ปานกลาง",3, IF('Form Responses 1'!O14="น้อย",2, IF('Form Responses 1'!O14="ปรับปรุง",1))))) -> 4 | G14: คนที่ 13 | H14: =IF('Form Responses 1'!Q14="ดีเยี่ยม",5, IF('Form Responses 1'!Q14="ดี",4, IF('Form Responses 1'!Q14="ปานกลาง",3, IF('Form Responses 1'!Q14="น้อย",2, IF('Form Responses 1'!Q14="ปรับปรุง",1))))) -> 4 | L14: คนที่ 13 | M14: =IF('Form Responses 1'!S14="ดีเยี่ยม",5, IF('Form Responses 1'!S14="ดี",4, IF('Form Responses 1'!S14="ปานกลาง",3, IF('Form Responses 1'!S14="น้อย",2, IF('Form Responses 1'!S14="ปรับปรุง",1))))) -> 5
... B26: คนที่ 25 | C26: =IF('Form Responses 1'!O26="ดีเยี่ยม",5, IF('Form Responses 1'!O26="ดี",4, IF('Form Responses 1'!O26="ปานกลาง",3, IF('Form Responses 1'!O26="น้อย",2, IF('Form Responses 1'!O26="ปรับปรุง",1))))) -> 5 | G26: คนที่ 25 | H26: =IF('Form Responses 1'!Q26="ดีเยี่ยม",5, IF('Form Responses 1'!Q26="ดี",4, IF('Form Responses 1'!Q26="ปานกลาง",3, IF('Form Responses 1'!Q26="น้อย",2, IF('Form Responses 1'!Q26="ปรับปรุง",1))))) -> 5 | L26: คนที่ 25 | M26: =IF('Form Responses 1'!S26="ดีเยี่ยม",5, IF('Form Responses 1'!S26="ดี",4, IF('Form Responses 1'!S26="ปานกลาง",3, IF('Form Responses 1'!S26="น้อย",2, IF('Form Responses 1'!S26="ปรับปรุง",1))))) -> 5
A32: ค่าเฉลี่ย | C32: =MEDIAN(C2:C31) -> 5 | F32: ค่าเฉลี่ย | H32: =MEDIAN(H2:H31) -> 5 | K32: ค่าเฉลี่ย | M32: =MEDIAN(M2:M31) -> 5
A34: 2 | B34: คนที่ 1 | C34: =IF('Form Responses 1'!P2="ดีเยี่ยม",5, IF('Form Responses 1'!P2="ดี",4, IF('Form Responses 1'!P2="ปานกลาง",3, IF('Form Responses 1'!P2="น้อย",2, IF('Form Responses 1'!P2="ปรับปรุง",1))))) -> 4 | F34: 4 | G34: คนที่ 1 | H34: =IF('Form Responses 1'!R2="ดีเยี่ยม",5, IF('Form Responses 1'!R2="ดี",4, IF('Form Responses 1'!R2="ปานกลาง",3, IF('Form Responses 1'!R2="น้อย",2, IF('Form Responses 1'!R2="ปรับปรุง",1))))) -> 4
B35: คนที่ 2 | C35: =IF('Form Responses 1'!P3="ดีเยี่ยม",5, IF('Form Responses 1'!P3="ดี",4, IF('Form Responses 1'!P3="ปานกลาง",3, IF('Form Responses 1'!P3="น้อย",2, IF('Form Responses 1'!P3="ปรับปรุง",1))))) -> 5 | G35: คนที่ 2 | H35: =IF('Form Responses 1'!R3="ดีเยี่ยม",5, IF('Form Responses 1'!R3="ดี",4, IF('Form Responses 1'!R3="ปานกลาง",3, IF('Form Responses 1'!R3="น้อย",2, IF('Form Responses 1'!R3="ปรับปรุง",1))))) -> 5
B36: คนที่ 3 | C36: =IF('Form Responses 1'!P4="ดีเยี่ยม",5, IF('Form Responses 1'!P4="ดี",4, IF('Form Responses 1'!P4="ปานกลาง",3, IF('Form Responses 1'!P4="น้อย",2, IF('Form Responses 1'!P4="ปรับปรุง",1))))) -> 4 | G36: คนที่ 3 | H36: =IF('Form Responses 1'!R4="ดีเยี่ยม",5, IF('Form Responses 1'!R4="ดี",4, IF('Form Responses 1'!R4="ปานกลาง",3, IF('Form Responses 1'!R4="น้อย",2, IF('Form Responses 1'!R4="ปรับปรุง",1))))) -> 5
B37: คนที่ 4 | C37: =IF('Form Responses 1'!P5="ดีเยี่ยม",5, IF('Form Responses 1'!P5="ดี",4, IF('Form Responses 1'!P5="ปานกลาง",3, IF('Form Responses 1'!P5="น้อย",2, IF('Form Responses 1'!P5="ปรับปรุง",1))))) -> 4 | G37: คนที่ 4 | H37: =IF('Form Responses 1'!R5="ดีเยี่ยม",5, IF('Form Responses 1'!R5="ดี",4, IF('Form Responses 1'!R5="ปานกลาง",3, IF('Form Responses 1'!R5="น้อย",2, IF('Form Responses 1'!R5="ปรับปรุง",1))))) -> 4
B38: คนที่ 5 | C38: =IF('Form Responses 1'!P6="ดีเยี่ยม",5, IF('Form Responses 1'!P6="ดี",4, IF('Form Responses 1'!P6="ปานกลาง",3, IF('Form Responses 1'!P6="น้อย",2, IF('Form Responses 1'!P6="ปรับปรุง",1))))) -> 5 | G38: คนที่ 5 | H38: =IF('Form Responses 1'!R6="ดีเยี่ยม",5, IF('Form Responses 1'!R6="ดี",4, IF('Form Responses 1'!R6="ปานกลาง",3, IF('Form Responses 1'!R6="น้อย",2, IF('Form Responses 1'!R6="ปรับปรุง",1))))) -> 5
B39: คนที่ 6 | C39: =IF('Form Responses 1'!P7="ดีเยี่ยม",5, IF('Form Responses 1'!P7="ดี",4, IF('Form Responses 1'!P7="ปานกลาง",3, IF('Form Responses 1'!P7="น้อย",2, IF('Form Responses 1'!P7="ปรับปรุง",1))))) -> 5 | G39: คนที่ 6 | H39: =IF('Form Responses 1'!R7="ดีเยี่ยม",5, IF('Form Responses 1'!R7="ดี",4, IF('Form Responses 1'!R7="ปานกลาง",3, IF('Form Responses 1'!R7="น้อย",2, IF('Form Responses 1'!R7="ปรับปรุง",1))))) -> 4
B40: คนที่ 7 | C40: =IF('Form Responses 1'!P8="ดีเยี่ยม",5, IF('Form Responses 1'!P8="ดี",4, IF('Form Responses 1'!P8="ปานกลาง",3, IF('Form Responses 1'!P8="น้อย",2, IF('Form Responses 1'!P8="ปรับปรุง",1))))) -> 5 | G40: คนที่ 7 | H40: =IF('Form Responses 1'!R8="ดีเยี่ยม",5, IF('Form Responses 1'!R8="ดี",4, IF('Form Responses 1'!R8="ปานกลาง",3, IF('Form Responses 1'!R8="น้อย",2, IF('Form Responses 1'!R8="ปรับปรุง",1))))) -> 4
B41: คนที่ 8 | C41: =IF('Form Responses 1'!P9="ดีเยี่ยม",5, IF('Form Responses 1'!P9="ดี",4, IF('Form Responses 1'!P9="ปานกลาง",3, IF('Form Responses 1'!P9="น้อย",2, IF('Form Responses 1'!P9="ปรับปรุง",1))))) -> 5 | G41: คนที่ 8 | H41: =IF('Form Responses 1'!R9="ดีเยี่ยม",5, IF('Form Responses 1'!R9="ดี",4, IF('Form Responses 1'!R9="ปานกลาง",3, IF('Form Responses 1'!R9="น้อย",2, IF('Form Responses 1'!R9="ปรับปรุง",1))))) -> 4
B42: คนที่ 9 | C42: =IF('Form Responses 1'!P10="ดีเยี่ยม",5, IF('Form Responses 1'!P10="ดี",4, IF('Form Responses 1'!P10="ปานกลาง",3, IF('Form Responses 1'!P10="น้อย",2, IF('Form Responses 1'!P10="ปรับปรุง",1))))) -> 5 | G42: คนที่ 9 | H42: =IF('Form Responses 1'!R10="ดีเยี่ยม",5, IF('Form Responses 1'!R10="ดี",4, IF('Form Responses 1'!R10="ปานกลาง",3, IF('Form Responses 1'!R10="น้อย",2, IF('Form Responses 1'!R10="ปรับปรุง",1))))) -> 5
B43: คนที่ 10 | C43: =IF('Form Responses 1'!P11="ดีเยี่ยม",5, IF('Form Responses 1'!P11="ดี",4, IF('Form Responses 1'!P11="ปานกลาง",3, IF('Form Responses 1'!P11="น้อย",2, IF('Form Responses 1'!P11="ปรับปรุง",1))))) -> 5 | G43: คนที่ 10 | H43: =IF('Form Responses 1'!R11="ดีเยี่ยม",5, IF('Form Responses 1'!R11="ดี",4, IF('Form Responses 1'!R11="ปานกลาง",3, IF('Form Responses 1'!R11="น้อย",2, IF('Form Responses 1'!R11="ปรับปรุง",1))))) -> 5
B44: คนที่ 11 | C44: =IF('Form Responses 1'!P12="ดีเยี่ยม",5, IF('Form Responses 1'!P12="ดี",4, IF('Form Responses 1'!P12="ปานกลาง",3, IF('Form Responses 1'!P12="น้อย",2, IF('Form Responses 1'!P12="ปรับปรุง",1))))) -> 5 | G44: คนที่ 11 | H44: =IF('Form Responses 1'!R12="ดีเยี่ยม",5, IF('Form Responses 1'!R12="ดี",4, IF('Form Responses 1'!R12="ปานกลาง",3, IF('Form Responses 1'!R12="น้อย",2, IF('Form Responses 1'!R12="ปรับปรุง",1))))) -> 5
B45: คนที่ 12 | C45: =IF('Form Responses 1'!P13="ดีเยี่ยม",5, IF('Form Responses 1'!P13="ดี",4, IF('Form Responses 1'!P13="ปานกลาง",3, IF('Form Responses 1'!P13="น้อย",2, IF('Form Responses 1'!P13="ปรับปรุง",1))))) -> 5 | G45: คนที่ 12 | H45: =IF('Form Responses 1'!R13="ดีเยี่ยม",5, IF('Form Responses 1'!R13="ดี",4, IF('Form Responses 1'!R13="ปานกลาง",3, IF('Form Responses 1'!R13="น้อย",2, IF('Form Responses 1'!R13="ปรับปรุง",1))))) -> 4
B46: คนที่ 13 | C46: =IF('Form Responses 1'!P14="ดีเยี่ยม",5, IF('Form Responses 1'!P14="ดี",4, IF('Form Responses 1'!P14="ปานกลาง",3, IF('Form Responses 1'!P14="น้อย",2, IF('Form Responses 1'!P14="ปรับปรุง",1))))) -> 4 | G46: คนที่ 13 | H46: =IF('Form Responses 1'!R14="ดีเยี่ยม",5, IF('Form Responses 1'!R14="ดี",4, IF('Form Responses 1'!R14="ปานกลาง",3, IF('Form Responses 1'!R14="น้อย",2, IF('Form Responses 1'!R14="ปรับปรุง",1))))) -> 4
... B58: คนที่ 25 | C58: =IF('Form Responses 1'!P26="ดีเยี่ยม",5, IF('Form Responses 1'!P26="ดี",4, IF('Form Responses 1'!P26="ปานกลาง",3, IF('Form Responses 1'!P26="น้อย",2, IF('Form Responses 1'!P26="ปรับปรุง",1))))) -> 5 | G58: คนที่ 25 | H58: =IF('Form Responses 1'!R26="ดีเยี่ยม",5, IF('Form Responses 1'!R26="ดี",4, IF('Form Responses 1'!R26="ปานกลาง",3, IF('Form Responses 1'!R26="น้อย",2, IF('Form Responses 1'!R26="ปรับปรุง",1))))) -> 5
A64: ค่าเฉลี่ย | C64: =MEDIAN(C34:C63) -> 5 | F64: ค่าเฉลี่ย | H64: =MEDIAN(H34:H63) -> 5

Sheet score3
A1: ข้อที่ | B1: จำนวนคน | C1: คะแนน | F1: ข้อที่ | G1: จำนวนคน | H1: คะแนน | K1: ข้อที่ | L1: จำนวนคน | M1: คะแนน
A2: 1 | B2: คนที่ 1 | C2: =IF('Form Responses 1'!T2="ดีเยี่ยม",5, IF('Form Responses 1'!T2="ดี",4, IF('Form Responses 1'!T2="ปานกลาง",3, IF('Form Responses 1'!T2="น้อย",2, IF('Form Responses 1'!T2="ปรับปรุง",1))))) -> 4 | F2: 3 | G2: คนที่ 1 | H2: =IF('Form Responses 1'!V2="ดีเยี่ยม",5, IF('Form Responses 1'!V2="ดี",4, IF('Form Responses 1'!V2="ปานกลาง",3, IF('Form Responses 1'!V2="น้อย",2, IF('Form Responses 1'!V2="ปรับปรุง",1))))) -> 4 | K2: 5 | L2: คนที่ 1 | M2: =IF('Form Responses 1'!X2="ดีเยี่ยม",5, IF('Form Responses 1'!X2="ดี",4, IF('Form Responses 1'!X2="ปานกลาง",3, IF('Form Responses 1'!X2="น้อย",2, IF('Form Responses 1'!X2="ปรับปรุง",1))))) -> 4
B3: คนที่ 2 | C3: =IF('Form Responses 1'!T3="ดีเยี่ยม",5, IF('Form Responses 1'!T3="ดี",4, IF('Form Responses 1'!T3="ปานกลาง",3, IF('Form Responses 1'!T3="น้อย",2, IF('Form Responses 1'!T3="ปรับปรุง",1))))) -> 4 | G3: คนที่ 2 | H3: =IF('Form Responses 1'!V3="ดีเยี่ยม",5, IF('Form Responses 1'!V3="ดี",4, IF('Form Responses 1'!V3="ปานกลาง",3, IF('Form Responses 1'!V3="น้อย",2, IF('Form Responses 1'!V3="ปรับปรุง",1))))) -> 5 | L3: คนที่ 2 | M3: =IF('Form Responses 1'!X3="ดีเยี่ยม",5, IF('Form Responses 1'!X3="ดี",4, IF('Form Responses 1'!X3="ปานกลาง",3, IF('Form Responses 1'!X3="น้อย",2, IF('Form Responses 1'!X3="ปรับปรุง",1))))) -> 4
B4: คนที่ 3 | C4: =IF('Form Responses 1'!T4="ดีเยี่ยม",5, IF('Form Responses 1'!T4="ดี",4, IF('Form Responses 1'!T4="ปานกลาง",3, IF('Form Responses 1'!T4="น้อย",2, IF('Form Responses 1'!T4="ปรับปรุง",1))))) -> 4 | G4: คนที่ 3 | H4: =IF('Form Responses 1'!V4="ดีเยี่ยม",5, IF('Form Responses 1'!V4="ดี",4, IF('Form Responses 1'!V4="ปานกลาง",3, IF('Form Responses 1'!V4="น้อย",2, IF('Form Responses 1'!V4="ปรับปรุง",1))))) -> 5 | L4: คนที่ 3 | M4: =IF('Form Responses 1'!X4="ดีเยี่ยม",5, IF('Form Responses 1'!X4="ดี",4, IF('Form Responses 1'!X4="ปานกลาง",3, IF('Form Responses 1'!X4="น้อย",2, IF('Form Responses 1'!X4="ปรับปรุง",1))))) -> 5
B5: คนที่ 4 | C5: =IF('Form Responses 1'!T5="ดีเยี่ยม",5, IF('Form Responses 1'!T5="ดี",4, IF('Form Responses 1'!T5="ปานกลาง",3, IF('Form Responses 1'!T5="น้อย",2, IF('Form Responses 1'!T5="ปรับปรุง",1))))) -> 5 | G5: คนที่ 4 | H5: =IF('Form Responses 1'!V5="ดีเยี่ยม",5, IF('Form Responses 1'!V5="ดี",4, IF('Form Responses 1'!V5="ปานกลาง",3, IF('Form Responses 1'!V5="น้อย",2, IF('Form Responses 1'!V5="ปรับปรุง",1))))) -> 5 | L5: คนที่ 4 | M5: =IF('Form Responses 1'!X5="ดีเยี่ยม",5, IF('Form Responses 1'!X5="ดี",4, IF('Form Responses 1'!X5="ปานกลาง",3, IF('Form Responses 1'!X5="น้อย",2, IF('Form Responses 1'!X5="ปรับปรุง",1))))) -> 5
B6: คนที่ 5 | C6: =IF('Form Responses 1'!T6="ดีเยี่ยม",5, IF('Form Responses 1'!T6="ดี",4, IF('Form Responses 1'!T6="ปานกลาง",3, IF('Form Responses 1'!T6="น้อย",2, IF('Form Responses 1'!T6="ปรับปรุง",1))))) -> 5 | G6: คนที่ 5 | H6: =IF('Form Responses 1'!V6="ดีเยี่ยม",5, IF('Form Responses 1'!V6="ดี",4, IF('Form Responses 1'!V6="ปานกลาง",3, IF('Form Responses 1'!V6="น้อย",2, IF('Form Responses 1'!V6="ปรับปรุง",1))))) -> 5 | L6: คนที่ 5 | M6: =IF('Form Responses 1'!X6="ดีเยี่ยม",5, IF('Form Responses 1'!X6="ดี",4, IF('Form Responses 1'!X6="ปานกลาง",3, IF('Form Responses 1'!X6="น้อย",2, IF('Form Responses 1'!X6="ปรับปรุง",1))))) -> 5
B7: คนที่ 6 | C7: =IF('Form Responses 1'!T7="ดีเยี่ยม",5, IF('Form Responses 1'!T7="ดี",4, IF('Form Responses 1'!T7="ปานกลาง",3, IF('Form Responses 1'!T7="น้อย",2, IF('Form Responses 1'!T7="ปรับปรุง",1))))) -> 4 | G7: คนที่ 6 | H7: =IF('Form Responses 1'!V7="ดีเยี่ยม",5, IF('Form Responses 1'!V7="ดี",4, IF('Form Responses 1'!V7="ปานกลาง",3, IF('Form Responses 1'!V7="น้อย",2, IF('Form Responses 1'!V7="ปรับปรุง",1))))) -> 5 | L7: คนที่ 6 | M7: =IF('Form Responses 1'!X7="ดีเยี่ยม",5, IF('Form Responses 1'!X7="ดี",4, IF('Form Responses 1'!X7="ปานกลาง",3, IF('Form Responses 1'!X7="น้อย",2, IF('Form Responses 1'!X7="ปรับปรุง",1))))) -> 5
B8: คนที่ 7 | C8: =IF('Form Responses 1'!T8="ดีเยี่ยม",5, IF('Form Responses 1'!T8="ดี",4, IF('Form Responses 1'!T8="ปานกลาง",3, IF('Form Responses 1'!T8="น้อย",2, IF('Form Responses 1'!T8="ปรับปรุง",1))))) -> 5 | G8: คนที่ 7 | H8: =IF('Form Responses 1'!V8="ดีเยี่ยม",5, IF('Form Responses 1'!V8="ดี",4, IF('Form Responses 1'!V8="ปานกลาง",3, IF('Form Responses 1'!V8="น้อย",2, IF('Form Responses 1'!V8="ปรับปรุง",1))))) -> 5 | L8: คนที่ 7 | M8: =IF('Form Responses 1'!X8="ดีเยี่ยม",5, IF('Form Responses 1'!X8="ดี",4, IF('Form Responses 1'!X8="ปานกลาง",3, IF('Form Responses 1'!X8="น้อย",2, IF('Form Responses 1'!X8="ปรับปรุง",1))))) -> 5
B9: คนที่ 8 | C9: =IF('Form Responses 1'!T9="ดีเยี่ยม",5, IF('Form Responses 1'!T9="ดี",4, IF('Form Responses 1'!T9="ปานกลาง",3, IF('Form Responses 1'!T9="น้อย",2, IF('Form Responses 1'!T9="ปรับปรุง",1))))) -> 5 | G9: คนที่ 8 | H9: =IF('Form Responses 1'!V9="ดีเยี่ยม",5, IF('Form Responses 1'!V9="ดี",4, IF('Form Responses 1'!V9="ปานกลาง",3, IF('Form Responses 1'!V9="น้อย",2, IF('Form Responses 1'!V9="ปรับปรุง",1))))) -> 5 | L9: คนที่ 8 | M9: =IF('Form Responses 1'!X9="ดีเยี่ยม",5, IF('Form Responses 1'!X9="ดี",4, IF('Form Responses 1'!X9="ปานกลาง",3, IF('Form Responses 1'!X9="น้อย",2, IF('Form Responses 1'!X9="ปรับปรุง",1))))) -> 5
B10: คนที่ 9 | C10: =IF('Form Responses 1'!T10="ดีเยี่ยม",5, IF('Form Responses 1'!T10="ดี",4, IF('Form Responses 1'!T10="ปานกลาง",3, IF('Form Responses 1'!T10="น้อย",2, IF('Form Responses 1'!T10="ปรับปรุง",1))))) -> 4 | G10: คนที่ 9 | H10: =IF('Form Responses 1'!V10="ดีเยี่ยม",5, IF('Form Responses 1'!V10="ดี",4, IF('Form Responses 1'!V10="ปานกลาง",3, IF('Form Responses 1'!V10="น้อย",2, IF('Form Responses 1'!V10="ปรับปรุง",1))))) -> 5 | L10: คนที่ 9 | M10: =IF('Form Responses 1'!X10="ดีเยี่ยม",5, IF('Form Responses 1'!X10="ดี",4, IF('Form Responses 1'!X10="ปานกลาง",3, IF('Form Responses 1'!X10="น้อย",2, IF('Form Responses 1'!X10="ปรับปรุง",1))))) -> 4
B11: คนที่ 10 | C11: =IF('Form Responses 1'!T11="ดีเยี่ยม",5, IF('Form Responses 1'!T11="ดี",4, IF('Form Responses 1'!T11="ปานกลาง",3, IF('Form Responses 1'!T11="น้อย",2, IF('Form Responses 1'!T11="ปรับปรุง",1))))) -> 5 | G11: คนที่ 10 | H11: =IF('Form Responses 1'!V11="ดีเยี่ยม",5, IF('Form Responses 1'!V11="ดี",4, IF('Form Responses 1'!V11="ปานกลาง",3, IF('Form Responses 1'!V11="น้อย",2, IF('Form Responses 1'!V11="ปรับปรุง",1))))) -> 5 | L11: คนที่ 10 | M11: =IF('Form Responses 1'!X11="ดีเยี่ยม",5, IF('Form Responses 1'!X11="ดี",4, IF('Form Responses 1'!X11="ปานกลาง",3, IF('Form Responses 1'!X11="น้อย",2, IF('Form Responses 1'!X11="ปรับปรุง",1))))) -> 5
B12: คนที่ 11 | C12: =IF('Form Responses 1'!T12="ดีเยี่ยม",5, IF('Form Responses 1'!T12="ดี",4, IF('Form Responses 1'!T12="ปานกลาง",3, IF('Form Responses 1'!T12="น้อย",2, IF('Form Responses 1'!T12="ปรับปรุง",1))))) -> 5 | G12: คนที่ 11 | H12: =IF('Form Responses 1'!V12="ดีเยี่ยม",5, IF('Form Responses 1'!V12="ดี",4, IF('Form Responses 1'!V12="ปานกลาง",3, IF('Form Responses 1'!V12="น้อย",2, IF('Form Responses 1'!V12="ปรับปรุง",1))))) -> 5 | L12: คนที่ 11 | M12: =IF('Form Responses 1'!X12="ดีเยี่ยม",5, IF('Form Responses 1'!X12="ดี",4, IF('Form Responses 1'!X12="ปานกลาง",3, IF('Form Responses 1'!X12="น้อย",2, IF('Form Responses 1'!X12="ปรับปรุง",1))))) -> 5
B13: คนที่ 12 | C13: =IF('Form Responses 1'!T13="ดีเยี่ยม",5, IF('Form Responses 1'!T13="ดี",4, IF('Form Responses 1'!T13="ปานกลาง",3, IF('Form Responses 1'!T13="น้อย",2, IF('Form Responses 1'!T13="ปรับปรุง",1))))) -> 5 | G13: คนที่ 12 | H13: =IF('Form Responses 1'!V13="ดีเยี่ยม",5, IF('Form Responses 1'!V13="ดี",4, IF('Form Responses 1'!V13="ปานกลาง",3, IF('Form Responses 1'!V13="น้อย",2, IF('Form Responses 1'!V13="ปรับปรุง",1))))) -> 5 | L13: คนที่ 12 | M13: =IF('Form Responses 1'!X13="ดีเยี่ยม",5, IF('Form Responses 1'!X13="ดี",4, IF('Form Responses 1'!X13="ปานกลาง",3, IF('Form Responses 1'!X13="น้อย",2, IF('Form Responses 1'!X13="ปรับปรุง",1))))) -> 5
B14: คนที่ 13 | C14: =IF('Form Responses 1'!T14="ดีเยี่ยม",5, IF('Form Responses 1'!T14="ดี",4, IF('Form Responses 1'!T14="ปานกลาง",3, IF('Form Responses 1'!T14="น้อย",2, IF('Form Responses 1'!T14="ปรับปรุง",1))))) -> 4 | G14: คนที่ 13 | H14: =IF('Form Responses 1'!V14="ดีเยี่ยม",5, IF('Form Responses 1'!V14="ดี",4, IF('Form Responses 1'!V14="ปานกลาง",3, IF('Form Responses 1'!V14="น้อย",2, IF('Form Responses 1'!V14="ปรับปรุง",1))))) -> 4 | L14: คนที่ 13 | M14: =IF('Form Responses 1'!X14="ดีเยี่ยม",5, IF('Form Responses 1'!X14="ดี",4, IF('Form Responses 1'!X14="ปานกลาง",3, IF('Form Responses 1'!X14="น้อย",2, IF('Form Responses 1'!X14="ปรับปรุง",1))))) -> 4
... B26: คนที่ 25 | C26: =IF('Form Responses 1'!T26="ดีเยี่ยม",5, IF('Form Responses 1'!T26="ดี",4, IF('Form Responses 1'!T26="ปานกลาง",3, IF('Form Responses 1'!T26="น้อย",2, IF('Form Responses 1'!T26="ปรับปรุง",1))))) -> 4 | G26: คนที่ 25 | H26: =IF('Form Responses 1'!V26="ดีเยี่ยม",5, IF('Form Responses 1'!V26="ดี",4, IF('Form Responses 1'!V26="ปานกลาง",3, IF('Form Responses 1'!V26="น้อย",2, IF('Form Responses 1'!V26="ปรับปรุง",1))))) -> 5 | L26: คนที่ 25 | M26: =IF('Form Responses 1'!X26="ดีเยี่ยม",5, IF('Form Responses 1'!X26="ดี",4, IF('Form Responses 1'!X26="ปานกลาง",3, IF('Form Responses 1'!X26="น้อย",2, IF('Form Responses 1'!X26="ปรับปรุง",1))))) -> 4
A32: ค่าเฉลี่ย | C32: =MEDIAN(C2:C31) -> 5 | F32: ค่าเฉลี่ย | H32: =MEDIAN(H2:H31) -> 5 | K32: ค่าเฉลี่ย | M32: =MEDIAN(M2:M31) -> 5
A34: 2 | B34: คนที่ 1 | C34: =IF('Form Responses 1'!U2="ดีเยี่ยม",5, IF('Form Responses 1'!U2="ดี",4, IF('Form Responses 1'!U2="ปานกลาง",3, IF('Form Responses 1'!U2="น้อย",2, IF('Form Responses 1'!U2="ปรับปรุง",1))))) -> 5 | F34: 4 | G34: คนที่ 1 | H34: =IF('Form Responses 1'!W2="ดีเยี่ยม",5, IF('Form Responses 1'!W2="ดี",4, IF('Form Responses 1'!W2="ปานกลาง",3, IF('Form Responses 1'!W2="น้อย",2, IF('Form Responses 1'!W2="ปรับปรุง",1))))) -> 4
B35: คนที่ 2 | C35: =IF('Form Responses 1'!U3="ดีเยี่ยม",5, IF('Form Responses 1'!U3="ดี",4, IF('Form Responses 1'!U3="ปานกลาง",3, IF('Form Responses 1'!U3="น้อย",2, IF('Form Responses 1'!U3="ปรับปรุง",1))))) -> 4 | G35: คนที่ 2 | H35: =IF('Form Responses 1'!W3="ดีเยี่ยม",5, IF('Form Responses 1'!W3="ดี",4, IF('Form Responses 1'!W3="ปานกลาง",3, IF('Form Responses 1'!W3="น้อย",2, IF('Form Responses 1'!W3="ปรับปรุง",1))))) -> 5
B36: คนที่ 3 | C36: =IF('Form Responses 1'!U4="ดีเยี่ยม",5, IF('Form Responses 1'!U4="ดี",4, IF('Form Responses 1'!U4="ปานกลาง",3, IF('Form Responses 1'!U4="น้อย",2, IF('Form Responses 1'!U4="ปรับปรุง",1))))) -> 5 | G36: คนที่ 3 | H36: =IF('Form Responses 1'!W4="ดีเยี่ยม",5, IF('Form Responses 1'!W4="ดี",4, IF('Form Responses 1'!W4="ปานกลาง",3, IF('Form Responses 1'!W4="น้อย",2, IF('Form Responses 1'!W4="ปรับปรุง",1))))) -> 4
B37: คนที่ 4 | C37: =IF('Form Responses 1'!U5="ดีเยี่ยม",5, IF('Form Responses 1'!U5="ดี",4, IF('Form Responses 1'!U5="ปานกลาง",3, IF('Form Responses 1'!U5="น้อย",2, IF('Form Responses 1'!U5="ปรับปรุง",1))))) -> 5 | G37: คนที่ 4 | H37: =IF('Form Responses 1'!W5="ดีเยี่ยม",5, IF('Form Responses 1'!W5="ดี",4, IF('Form Responses 1'!W5="ปานกลาง",3, IF('Form Responses 1'!W5="น้อย",2, IF('Form Responses 1'!W5="ปรับปรุง",1))))) -> 5
B38: คนที่ 5 | C38: =IF('Form Responses 1'!U6="ดีเยี่ยม",5, IF('Form Responses 1'!U6="ดี",4, IF('Form Responses 1'!U6="ปานกลาง",3, IF('Form Responses 1'!U6="น้อย",2, IF('Form Responses 1'!U6="ปรับปรุง",1))))) -> 5 | G38: คนที่ 5 | H38: =IF('Form Responses 1'!W6="ดีเยี่ยม",5, IF('Form Responses 1'!W6="ดี",4, IF('Form Responses 1'!W6="ปานกลาง",3, IF('Form Responses 1'!W6="น้อย",2, IF('Form Responses 1'!W6="ปรับปรุง",1))))) -> 5
B39: คนที่ 6 | C39: =IF('Form Responses 1'!U7="ดีเยี่ยม",5, IF('Form Responses 1'!U7="ดี",4, IF('Form Responses 1'!U7="ปานกลาง",3, IF('Form Responses 1'!U7="น้อย",2, IF('Form Responses 1'!U7="ปรับปรุง",1))))) -> 5 | G39: คนที่ 6 | H39: =IF('Form Responses 1'!W7="ดีเยี่ยม",5, IF('Form Responses 1'!W7="ดี",4, IF('Form Responses 1'!W7="ปานกลาง",3, IF('Form Responses 1'!W7="น้อย",2, IF('Form Responses 1'!W7="ปรับปรุง",1))))) -> 5
B40: คนที่ 7 | C40: =IF('Form Responses 1'!U8="ดีเยี่ยม",5, IF('Form Responses 1'!U8="ดี",4, IF('Form Responses 1'!U8="ปานกลาง",3, IF('Form Responses 1'!U8="น้อย",2, IF('Form Responses 1'!U8="ปรับปรุง",1))))) -> 4 | G40: คนที่ 7 | H40: =IF('Form Responses 1'!W8="ดีเยี่ยม",5, IF('Form Responses 1'!W8="ดี",4, IF('Form Responses 1'!W8="ปานกลาง",3, IF('Form Responses 1'!W8="น้อย",2, IF('Form Responses 1'!W8="ปรับปรุง",1))))) -> 5
B41: คนที่ 8 | C41: =IF('Form Responses 1'!U9="ดีเยี่ยม",5, IF('Form Responses 1'!U9="ดี",4, IF('Form Responses 1'!U9="ปานกลาง",3, IF('Form Responses 1'!U9="น้อย",2, IF('Form Responses 1'!U9="ปรับปรุง",1))))) -> 5 | G41: คนที่ 8 | H41: =IF('Form Responses 1'!W9="ดีเยี่ยม",5, IF('Form Responses 1'!W9="ดี",4, IF('Form Responses 1'!W9="ปานกลาง",3, IF('Form Responses 1'!W9="น้อย",2, IF('Form Responses 1'!W9="ปรับปรุง",1))))) -> 4
